Workbook

Sheet Summary
A1: Blocky Studio｜24个月持续发展资金规划｜人民币
A2: 建设目标：个人开源、教育组织后台、多端、Agent App与社区；未报价参数均是规划假设。
B4: 精简推进 | C4: 基准建设 | D4: 高用量压力
A5: 期末平台云算力活跃人头 | B5: =Cohorts!Y6 -> 464 | C5: =Cohorts!Y20 -> 1160 | D5: =Cohorts!Y34 -> 2320
A6: 用户Token采购（24月） | B6: =SUM(Costs!B11:Y11) -> 913809.77 | C6: =SUM(Costs!B36:Y36) -> 3046032.6 | D6: =SUM(Costs!B61:Y61) -> 15230163
A7: 研发工具与内部算力 | B7: =SUM(Costs!B5:Y5) -> 95348.811 | C7: =SUM(Costs!B30:Y30) -> 173361.47 | D7: =SUM(Costs!B55:Y55) -> 329386.8
A8: 等效人力综合现金 | B8: =SUM(Costs!B4:Y4) -> 1056000 | C8: =SUM(Costs!B29:Y29) -> 1800000 | D8: =SUM(Costs!B54:Y54) -> 2736000
A9: 其他常规与专项运营 | B9: =SUM(Costs!B17:Y17)-B7-B8 -> 474750 | C9: =SUM(Costs!B42:Y42)-C7-C8 -> 633000 | D9: =SUM(Costs!B67:Y67)-D7-D8 -> 949500
A10: 设备现金 | B10: =SUM(Costs!B14:Y14) -> 60000 | C10: =SUM(Costs!B39:Y39) -> 80000 | D10: =SUM(Costs!B64:Y64) -> 120000
A11: 24个月现金支付总额 | B11: =SUM('Cash Flow'!B15:Y15) -> 2599908.6 | C11: =SUM('Cash Flow'!B48:Y48) -> 5732394 | D11: =SUM('Cash Flow'!B81:Y81) -> 19365050
A12: 规划收款（默认不抵减） | B12: =SUM(Revenue!B5:Y5) -> 0 | C12: =SUM(Revenue!B17:Y17) -> 0 | D12: =SUM(Revenue!B29:Y29) -> 0
A13: 确认自有现金（未录入） | B13: =Assumptions!$B$4 -> 0 | C13: =Assumptions!$B$4 -> 0 | D13: =Assumptions!$B$4 -> 0
A14: 峰值现金缺口 | B14: =MAX(0,-MIN('Cash Flow'!B17:Y17)) -> 2599908.6 | C14: =MAX(0,-MIN('Cash Flow'!B50:Y50)) -> 5732394 | D14: =MAX(0,-MIN('Cash Flow'!B83:Y83)) -> 19365050
A15: 常规支出风险预留 | B15: =SUM(Costs!B17:Y17)*Assumptions!B$24 -> 162609.88 | C15: =SUM(Costs!B42:Y42)*Assumptions!C$24 -> 260636.15 | D15: =SUM(Costs!B67:Y67)*Assumptions!D$24 -> 602233.02
A16: 未使用厂商合作现金预留 | B16: =MAX(0,Assumptions!B$23-SUM(Costs!B12:Y12)-'Cash Flow'!Y21-'Cash Flow'!Y22) -> 100000 | C16: =MAX(0,Assumptions!C$23-SUM(Costs!B37:Y37)-'Cash Flow'!Y54-'Cash Flow'!Y55) -> 300000 | D16: =MAX(0,Assumptions!D$23-SUM(Costs!B62:Y62)-'Cash Flow'!Y87-'Cash Flow'!Y88) -> 800000
A17: 正常运营现金储备 | B17: =Assumptions!B$25*(Costs!Y18+Costs!Y11*(1-Assumptions!$B$5)) -> 824586.72 | C17: =Assumptions!C$25*(Costs!Y43+Costs!Y36*(1-Assumptions!$B$5)) -> 2371396.9 | D17: =Assumptions!D$25*(Costs!Y68+Costs!Y61*(1-Assumptions!$B$5)) -> 10671751
A18: 最低追加资金需求 | B18: =SUM(B14:B17) -> 3687105.2 | C18: =SUM(C14:C17) -> 8664427.1 | D18: =SUM(D14:D17) -> 31439033
A19: 建议资金规划目标（取整） | B19: =ROUNDUP(B18/Assumptions!$B$12,0)*Assumptions!$B$12 -> 4000000 | C19: =ROUNDUP(C18/Assumptions!$B$12,0)*Assumptions!$B$12 -> 9000000 | D19: =ROUNDUP(D18/Assumptions!$B$12,0)*Assumptions!$B$12 -> 31500000
A20: 假设足额补资的期末现金 | B20: ='Cash Flow'!Y20 -> 1400091.4 | C20: ='Cash Flow'!Y53 -> 3267606 | D20: ='Cash Flow'!Y86 -> 12134950
A21: 期末单月用户Token成本 | B21: =Costs!Y11 -> 203028.2 | C21: =Costs!Y36 -> 676760.68 | D21: =Costs!Y61 -> 3383803.4
A22: 峰值缺口月份 | B22: =TEXT(INDEX('Cash Flow'!B2:Y2,1,MATCH(MIN('Cash Flow'!B17:Y17),'Cash Flow'!B17:Y17,0)),"yyyy-mm") -> 2028-10 | C22: =TEXT(INDEX('Cash Flow'!B35:Y35,1,MATCH(MIN('Cash Flow'!B50:Y50),'Cash Flow'!B50:Y50,0)),"yyyy-mm") -> 2028-10 | D22: =TEXT(INDEX('Cash Flow'!B68:Y68,1,MATCH(MIN('Cash Flow'!B83:Y83),'Cash Flow'!B83:Y83,0)),"yyyy-mm") -> 2028-10
A24: 默认成本回收率0：只表示未确认收入不用于压低资金，不能解释为实际商业收入为零。
A26: 厂商费用0表示未录入；现金预留是风险预算，获得报价后更新费、预付和保证金。
A28: 精简与高用量同时改变人力、人数和成本，是资源情景；新增用量须有额度与回款支持。

Sheet Assumptions
A1: 人民币；蓝色为可调输入，全部未证实金额与规模是规划假设
A2: 规划月数 | B2: 24
A3: 起始月份（假设） | B3: 46327
A4: 已确认自有现金（未录入为0） | B4: 0
A5: 算力成本回收比例（非套餐价） | B5: 0
A6: 收款延迟月数 | B6: 0
A7: 非退还合作费（报价未录入） | B7: 0
A8: 可抵扣算力预付（报价未录入） | B8: 0
A9: 可退保证金（报价未录入） | B9: 0
A10: 厂商款支付月份 | B10: 6
A11: 设备折旧月数 | B11: 36
A12: 资金目标取整步长（元） | B12: 500000
A14: 费用与人数均是条件预算；厂商条款、实际自有资金及算力售价未确认。0表示未录入；真实场景在产品准备关口后，未确认收入不抵减资金。
B16: 精简推进 | C16: 基准建设 | D16: 高用量压力
A17: 前6月等效人力 | B17: 2 | C17: 3 | D17: 4
A18: 后18月等效人力 | B18: 3 | C18: 4 | D18: 5
A19: 综合人月成本（元） | B19: 16000 | C19: 20000 | D19: 24000
A20: 平台云用户规模倍率 | B20: 0.4 | C20: 1 | D20: 2
A21: 人均算力成本倍率 | B21: 0.75 | C21: 1 | D21: 2.5
A22: 其他建设成本倍率 | B22: 0.75 | C22: 1 | D22: 1.5
A23: 厂商合作现金预留（元） | B23: 100000 | C23: 300000 | D23: 800000
A24: 常规支出风险预留比例 | B24: 0.1 | C24: 0.1 | D24: 0.15
A25: 期末正常运营储备月数 | B25: 3 | C25: 3 | D25: 3
A29: 学生短任务参考月成本 | B29: =Usage!B19 -> 3.386124
A30: 教师短任务参考月成本 | B30: =Usage!B20 -> 20.316744
A31: 专业云创作者参考月成本 | B31: =Usage!B21 -> 1347.02
A32: 研发等效人力月度Agent预算 | B32: =Usage!B22 -> 1926.2386
A34: 基础设施前6月/月 | B34: 3000
A35: 基础设施第7至12月/月 | B35: 6000
A36: 基础设施后12月/月 | B36: 9000
A37: 教学共创前3月/月 | B37: 0
A38: 教学共创第4至12月/月 | B38: 6000
A39: 教学共创后12月/月 | B39: 8000
A40: 社区前3月/月 | B40: 0
A41: 社区第4至12月/月 | B41: 3000
A42: 社区后12月/月 | B42: 6000
A43: 一般运营/月 | B43: 3000
A46: 月序 | B46: 学生云活跃人数 | C46: 教师云活跃人数 | D46: 个人云活跃人数 | F46: 专项外部交付月份 | G46: 专项支出
A47: 1 | B47: 0 | C47: 0 | D47: 0 | F47: 6 | G47: 30000
A48: 2 | B48: 0 | C48: 0 | D48: 0 | F48: 12 | G48: 40000
...

Sheet Usage
A1: Token成本：项目短任务样本与专业开发者公开统计分开使用
A3: 有回执的任务数 | B3: 10
A4: 实际响应数 | B4: 30
A5: 美元兑人民币参考中间价 | B5: 6.7351
A6: 样本输入Token总量 | B6: 76845
A7: 样本输出Token总量 | B7: 5738
A8: Pro高峰未命中输入价（元/百万） | B8: 9
A9: Pro高峰输出价（元/百万） | B9: 27
A10: 学生每月活动次数（假设） | B10: 4
A11: 学生每活动任务尝试数（假设） | B11: 10
A12: 教师每月准备次数（假设） | B12: 12
A13: 教师每次任务尝试数（假设） | B13: 20
A14: 专业开发者典型月成本下限（美元） | B14: 150
... A18: 场景预算启用月序（条件假设） | B18: 19
A19: 学生人均月短任务参考成本 | B19: =B24*B10*B11 -> 3.386124
A20: 教师人均月短任务参考成本 | B20: =B24*B12*B13 -> 20.316744
A21: 专业云创作者人均月参考成本 | B21: =B15*B5 -> 1347.02
A22: 研发等效资源人均月Agent预算 | B22: =B17*B23*B5 -> 1926.2386
A23: 研发每月活跃天数（假设） | B23: 22
A24: 单任务按直供Pro峰价重定价（元） | B24: =(B6/B3*B8+B7/B3*B9)/1000000 -> 0.0846531
A25: 每任务平均输入Token | B25: =B6/B3 -> 7684.5
A26: 每任务平均输出Token | B26: =B7/B3 -> 573.8
A27: 专业月成本下限折人民币 | B27: =B14*B5 -> 1010.265
A28: 专业月成本上限折人民币 | B28: =B16*B5 -> 1683.775
A30: 样本仅涵盖10个有可读回执的短任务、30次响应；未取得缓存拆分。其他任务可能另有费用，不用成功样本估算其零消耗。
A31: 学生/教师频次为规划输入，短任务参考不代表真实课堂月成本或完整专业模板消耗；输入输出、上下文增长与重试须后续实测。
A32: 专业档单列Claude Code企业API使用统计150–250美元/月，中点为200；不套用于所有个人用户或小学生，不代表Blocky实测或厂商报价。
A33: 内部研发采用13美元/活跃日×22个活跃日的资源预算，活跃天数是工作负荷假设；公开典型月范围与活跃日均不能同时相加。
A34: DeepSeek价格来自当前中文API文档，缓存未知按全部未命中敏感性重定价；不能当成息壤实际支付账单。
A35: 汇率参考2026-09-30中国货币网6.7351，非支付成交汇率；美元统计先换算人民币再进入本模型。
A36: 前18个月为研发排期假设，场景预算第19月后且产品准备关口通过才启用；日期与人数均非上线承诺。关口延期时调整启用月与人数曲线。
A37: BYOK及本地用户不计平台采购人数。平台云算力专业档用户规模是条件容量，人头不等于下载、注册、订阅销量或既有客户。

Sheet Cohorts
A1: 精简推进
A2: 月份 | B2: =EDATE(Assumptions!$B$3,0) -> 46327 | C2: =EDATE(Assumptions!$B$3,1) -> 46357 | D2: =EDATE(Assumptions!$B$3,2) -> 46388 | E2: =EDATE(Assumptions!$B$3,3) -> 46419 | F2: =EDATE(Assumptions!$B$3,4) -> 46447 | G2: =EDATE(Assumptions!$B$3,5) -> 46478 | H2: =EDATE(Assumptions!$B$3,6) -> 46508 | I2: =EDATE(Assumptions!$B$3,7) -> 46539 | J2: =EDATE(Assumptions!$B$3,8) -> 46569 | K2: =EDATE(Assumptions!$B$3,9) -> 46600 | L2: =EDATE(Assumptions!$B$3,10) -> 46631 | M2: =EDATE(Assumptions!$B$3,11) -> 46661 | N2: =EDATE(Assumptions!$B$3,12) -> 46692 | O2: =EDATE(Assumptions!$B$3,13) -> 46722 | P2: =EDATE(Assumptions!$B$3,14) -> 46753 | Q2: =EDATE(Assumptions!$B$3,15) -> 46784 | R2: =EDATE(Assumptions!$B$3,16) -> 46813 | S2: =EDATE(Assumptions!$B$3,17) -> 46844 | T2: =EDATE(Assumptions!$B$3,18) -> 46874 | U2: =EDATE(Assumptions!$B$3,19) -> 46905 | V2: =EDATE(Assumptions!$B$3,20) -> 46935 | W2: =EDATE(Assumptions!$B$3,21) -> 46966 | X2: =EDATE(Assumptions!$B$3,22) -> 46997 | Y2: =EDATE(Assumptions!$B$3,23) -> 47027 | Z2: 24个月合计 / 期末
A3: 学生平台云算力条件容量 | B3: =IF(1>=Usage!$B$18,ROUND(Assumptions!B47*Assumptions!$B$20,0),0) -> 0 | C3: =IF(2>=Usage!$B$18,ROUND(Assumptions!B48*Assumptions!$B$20,0),0) -> 0 | D3: =IF(3>=Usage!$B$18,ROUND(Assumptions!B49*Assumptions!$B$20,0),0) -> 0 | E3: =IF(4>=Usage!$B$18,ROUND(Assumptions!B50*Assumptions!$B$20,0),0) -> 0 | F3: =IF(5>=Usage!$B$18,ROUND(Assumptions!B51*Assumptions!$B$20,0),0) -> 0 | G3: =IF(6>=Usage!$B$18,ROUND(Assumptions!B52*Assumptions!$B$20,0),0) -> 0 | H3: =IF(7>=Usage!$B$18,ROUND(Assumptions!B53*Assumptions!$B$20,0),0) -> 0 | I3: =IF(8>=Usage!$B$18,ROUND(Assumptions!B54*Assumptions!$B$20,0),0) -> 0 | J3: =IF(9>=Usage!$B$18,ROUND(Assumptions!B55*Assumptions!$B$20,0),0) -> 0 | K3: =IF(10>=Usage!$B$18,ROUND(Assumptions!B56*Assumptions!$B$20,0),0) -> 0 | L3: =IF(11>=Usage!$B$18,ROUND(Assumptions!B57*Assumptions!$B$20,0),0) -> 0 | M3: =IF(12>=Usage!$B$18,ROUND(Assumptions!B58*Assumptions!$B$20,0),0) -> 0 | N3: =IF(13>=Usage!$B$18,ROUND(Assumptions!B59*Assumptions!$B$20,0),0) -> 0 | O3: =IF(14>=Usage!$B$18,ROUND(Assumptions!B60*Assumptions!$B$20,0),0) -> 0 | P3: =IF(15>=Usage!$B$18,ROUND(Assumptions!B61*Assumptions!$B$20,0),0) -> 0 | Q3: =IF(16>=Usage!$B$18,ROUND(Assumptions!B62*Assumptions!$B$20,0),0) -> 0 | R3: =IF(17>=Usage!$B$18,ROUND(Assumptions!B63*Assumptions!$B$20,0),0) -> 0 | S3: =IF(18>=Usage!$B$18,ROUND(Assumptions!B64*Assumptions!$B$20,0),0) -> 0 | T3: =IF(19>=Usage!$B$18,ROUND(Assumptions!B65*Assumptions!$B$20,0),0) -> 120 | U3: =IF(20>=Usage!$B$18,ROUND(Assumptions!B66*Assumptions!$B$20,0),0) -> 120 | V3: =IF(21>=Usage!$B$18,ROUND(Assumptions!B67*Assumptions!$B$20,0),0) -> 120 | W3: =IF(22>=Usage!$B$18,ROUND(Assumptions!B68*Assumptions!$B$20,0),0) -> 240 | X3: =IF(23>=Usage!$B$18,ROUND(Assumptions!B69*Assumptions!$B$20,0),0) -> 240 | Y3: =IF(24>=Usage!$B$18,ROUND(Assumptions!B70*Assumptions!$B$20,0),0) -> 240 | Z3: =SUM(B3:Y3) -> 1080
A4: 教师平台云算力条件容量 | B4: =IF(1>=Usage!$B$18,ROUND(Assumptions!C47*Assumptions!$B$20,0),0) -> 0 | C4: =IF(2>=Usage!$B$18,ROUND(Assumptions!C48*Assumptions!$B$20,0),0) -> 0 | D4: =IF(3>=Usage!$B$18,ROUND(Assumptions!C49*Assumptions!$B$20,0),0) -> 0 | E4: =IF(4>=Usage!$B$18,ROUND(Assumptions!C50*Assumptions!$B$20,0),0) -> 0 | F4: =IF(5>=Usage!$B$18,ROUND(Assumptions!C51*Assumptions!$B$20,0),0) -> 0 | G4: =IF(6>=Usage!$B$18,ROUND(Assumptions!C52*Assumptions!$B$20,0),0) -> 0 | H4: =IF(7>=Usage!$B$18,ROUND(Assumptions!C53*Assumptions!$B$20,0),0) -> 0 | I4: =IF(8>=Usage!$B$18,ROUND(Assumptions!C54*Assumptions!$B$20,0),0) -> 0 | J4: =IF(9>=Usage!$B$18,ROUND(Assumptions!C55*Assumptions!$B$20,0),0) -> 0 | K4: =IF(10>=Usage!$B$18,ROUND(Assumptions!C56*Assumptions!$B$20,0),0) -> 0 | L4: =IF(11>=Usage!$B$18,ROUND(Assumptions!C57*Assumptions!$B$20,0),0) -> 0 | M4: =IF(12>=Usage!$B$18,ROUND(Assumptions!C58*Assumptions!$B$20,0),0) -> 0 | N4: =IF(13>=Usage!$B$18,ROUND(Assumptions!C59*Assumptions!$B$20,0),0) -> 0 | O4: =IF(14>=Usage!$B$18,ROUND(Assumptions!C60*Assumptions!$B$20,0),0) -> 0 | P4: =IF(15>=Usage!$B$18,ROUND(Assumptions!C61*Assumptions!$B$20,0),0) -> 0 | Q4: =IF(16>=Usage!$B$18,ROUND(Assumptions!C62*Assumptions!$B$20,0),0) -> 0 | R4: =IF(17>=Usage!$B$18,ROUND(Assumptions!C63*Assumptions!$B$20,0),0) -> 0 | S4: =IF(18>=Usage!$B$18,ROUND(Assumptions!C64*Assumptions!$B$20,0),0) -> 0 | T4: =IF(19>=Usage!$B$18,ROUND(Assumptions!C65*Assumptions!$B$20,0),0) -> 16 | U4: =IF(20>=Usage!$B$18,ROUND(Assumptions!C66*Assumptions!$B$20,0),0) -> 16 | V4: =IF(21>=Usage!$B$18,ROUND(Assumptions!C67*Assumptions!$B$20,0),0) -> 16 | W4: =IF(22>=Usage!$B$18,ROUND(Assumptions!C68*Assumptions!$B$20,0),0) -> 24 | X4: =IF(23>=Usage!$B$18,ROUND(Assumptions!C69*Assumptions!$B$20,0),0) -> 24 | Y4: =IF(24>=Usage!$B$18,ROUND(Assumptions!C70*Assumptions!$B$20,0),0) -> 24 | Z4: =SUM(B4:Y4) -> 120
A5: 专业创作者平台云算力条件容量 | B5: =IF(1>=Usage!$B$18,ROUND(Assumptions!D47*Assumptions!$B$20,0),0) -> 0 | C5: =IF(2>=Usage!$B$18,ROUND(Assumptions!D48*Assumptions!$B$20,0),0) -> 0 | D5: =IF(3>=Usage!$B$18,ROUND(Assumptions!D49*Assumptions!$B$20,0),0) -> 0 | E5: =IF(4>=Usage!$B$18,ROUND(Assumptions!D50*Assumptions!$B$20,0),0) -> 0 | F5: =IF(5>=Usage!$B$18,ROUND(Assumptions!D51*Assumptions!$B$20,0),0) -> 0 | G5: =IF(6>=Usage!$B$18,ROUND(Assumptions!D52*Assumptions!$B$20,0),0) -> 0 | H5: =IF(7>=Usage!$B$18,ROUND(Assumptions!D53*Assumptions!$B$20,0),0) -> 0 | I5: =IF(8>=Usage!$B$18,ROUND(Assumptions!D54*Assumptions!$B$20,0),0) -> 0 | J5: =IF(9>=Usage!$B$18,ROUND(Assumptions!D55*Assumptions!$B$20,0),0) -> 0 | K5: =IF(10>=Usage!$B$18,ROUND(Assumptions!D56*Assumptions!$B$20,0),0) -> 0 | L5: =IF(11>=Usage!$B$18,ROUND(Assumptions!D57*Assumptions!$B$20,0),0) -> 0 | M5: =IF(12>=Usage!$B$18,ROUND(Assumptions!D58*Assumptions!$B$20,0),0) -> 0 | N5: =IF(13>=Usage!$B$18,ROUND(Assumptions!D59*Assumptions!$B$20,0),0) -> 0 | O5: =IF(14>=Usage!$B$18,ROUND(Assumptions!D60*Assumptions!$B$20,0),0) -> 0 | P5: =IF(15>=Usage!$B$18,ROUND(Assumptions!D61*Assumptions!$B$20,0),0) -> 0 | Q5: =IF(16>=Usage!$B$18,ROUND(Assumptions!D62*Assumptions!$B$20,0),0) -> 0 | R5: =IF(17>=Usage!$B$18,ROUND(Assumptions!D63*Assumptions!$B$20,0),0) -> 0 | S5: =IF(18>=Usage!$B$18,ROUND(Assumptions!D64*Assumptions!$B$20,0),0) -> 0 | T5: =IF(19>=Usage!$B$18,ROUND(Assumptions!D65*Assumptions!$B$20,0),0) -> 100 | U5: =IF(20>=Usage!$B$18,ROUND(Assumptions!D66*Assumptions!$B$20,0),0) -> 100 | V5: =IF(21>=Usage!$B$18,ROUND(Assumptions!D67*Assumptions!$B$20,0),0) -> 100 | W5: =IF(22>=Usage!$B$18,ROUND(Assumptions!D68*Assumptions!$B$20,0),0) -> 200 | X5: =IF(23>=Usage!$B$18,ROUND(Assumptions!D69*Assumptions!$B$20,0),0) -> 200 | Y5: =IF(24>=Usage!$B$18,ROUND(Assumptions!D70*Assumptions!$B$20,0),0) -> 200 | Z5: =SUM(B5:Y5) -> 900
A6: 合计云算力人头（非下载数） | B6: =SUM(B3:B5) -> 0 | C6: =SUM(C3:C5) -> 0 | D6: =SUM(D3:D5) -> 0 | E6: =SUM(E3:E5) -> 0 | F6: =SUM(F3:F5) -> 0 | G6: =SUM(G3:G5) -> 0 | H6: =SUM(H3:H5) -> 0 | I6: =SUM(I3:I5) -> 0 | ... Y6: =SUM(Y3:Y5) -> 464 | Z6: =Y6 -> 464
A7: 学生月度算力采购 | B7: =B3*Assumptions!$B$29*Assumptions!$B$21 -> 0 | C7: =C3*Assumptions!$B$29*Assumptions!$B$21 -> 0 | D7: =D3*Assumptions!$B$29*Assumptions!$B$21 -> 0 | E7: =E3*Assumptions!$B$29*Assumptions!$B$21 -> 0 | F7: =F3*Assumptions!$B$29*Assumptions!$B$21 -> 0 | G7: =G3*Assumptions!$B$29*Assumptions!$B$21 -> 0 | H7: =H3*Assumptions!$B$29*Assumptions!$B$21 -> 0 | I7: =I3*Assumptions!$B$29*Assumptions!$B$21 -> 0 | ... Y7: =Y3*Assumptions!$B$29*Assumptions!$B$21 -> 609.50232 | Z7: =SUM(B7:Y7) -> 2742.7604
A8: 教师月度算力采购 | B8: =B4*Assumptions!$B$30*Assumptions!$B$21 -> 0 | C8: =C4*Assumptions!$B$30*Assumptions!$B$21 -> 0 | D8: =D4*Assumptions!$B$30*Assumptions!$B$21 -> 0 | E8: =E4*Assumptions!$B$30*Assumptions!$B$21 -> 0 | F8: =F4*Assumptions!$B$30*Assumptions!$B$21 -> 0 | G8: =G4*Assumptions!$B$30*Assumptions!$B$21 -> 0 | H8: =H4*Assumptions!$B$30*Assumptions!$B$21 -> 0 | I8: =I4*Assumptions!$B$30*Assumptions!$B$21 -> 0 | ... Y8: =Y4*Assumptions!$B$30*Assumptions!$B$21 -> 365.70139 | Z8: =SUM(B8:Y8) -> 1828.507
A9: 个人月度算力采购 | B9: =B5*Assumptions!$B$31*Assumptions!$B$21 -> 0 | C9: =C5*Assumptions!$B$31*Assumptions!$B$21 -> 0 | D9: =D5*Assumptions!$B$31*Assumptions!$B$21 -> 0 | E9: =E5*Assumptions!$B$31*Assumptions!$B$21 -> 0 | F9: =F5*Assumptions!$B$31*Assumptions!$B$21 -> 0 | G9: =G5*Assumptions!$B$31*Assumptions!$B$21 -> 0 | H9: =H5*Assumptions!$B$31*Assumptions!$B$21 -> 0 | I9: =I5*Assumptions!$B$31*Assumptions!$B$21 -> 0 | ... Y9: =Y5*Assumptions!$B$31*Assumptions!$B$21 -> 202053 | Z9: =SUM(B9:Y9) -> 909238.5
A10: 外部用户Token成本合计 | B10: =SUM(B7:B9) -> 0 | C10: =SUM(C7:C9) -> 0 | D10: =SUM(D7:D9) -> 0 | E10: =SUM(E7:E9) -> 0 | F10: =SUM(F7:F9) -> 0 | G10: =SUM(G7:G9) -> 0 | H10: =SUM(H7:H9) -> 0 | I10: =SUM(I7:I9) -> 0 | ... Y10: =SUM(Y7:Y9) -> 203028.2 | Z10: =SUM(B10:Y10) -> 913809.77
A15: 基准建设
A16: 月份 | B16: =EDATE(Assumptions!$B$3,0) -> 46327 | C16: =EDATE(Assumptions!$B$3,1) -> 46357 | D16: =EDATE(Assumptions!$B$3,2) -> 46388 | E16: =EDATE(Assumptions!$B$3,3) -> 46419 | F16: =EDATE(Assumptions!$B$3,4) -> 46447 | G16: =EDATE(Assumptions!$B$3,5) -> 46478 | H16: =EDATE(Assumptions!$B$3,6) -> 46508 | I16: =EDATE(Assumptions!$B$3,7) -> 46539 | J16: =EDATE(Assumptions!$B$3,8) -> 46569 | K16: =EDATE(Assumptions!$B$3,9) -> 46600 | L16: =EDATE(Assumptions!$B$3,10) -> 46631 | M16: =EDATE(Assumptions!$B$3,11) -> 46661 | N16: =EDATE(Assumptions!$B$3,12) -> 46692 | O16: =EDATE(Assumptions!$B$3,13) -> 46722 | P16: =EDATE(Assumptions!$B$3,14) -> 46753 | Q16: =EDATE(Assumptions!$B$3,15) -> 46784 | R16: =EDATE(Assumptions!$B$3,16) -> 46813 | S16: =EDATE(Assumptions!$B$3,17) -> 46844 | T16: =EDATE(Assumptions!$B$3,18) -> 46874 | U16: =EDATE(Assumptions!$B$3,19) -> 46905 | V16: =EDATE(Assumptions!$B$3,20) -> 46935 | W16: =EDATE(Assumptions!$B$3,21) -> 46966 | X16: =EDATE(Assumptions!$B$3,22) -> 46997 | Y16: =EDATE(Assumptions!$B$3,23) -> 47027 | Z16: 24个月合计 / 期末
A17: 学生平台云算力条件容量 | B17: =IF(1>=Usage!$B$18,ROUND(Assumptions!B47*Assumptions!$C$20,0),0) -> 0 | C17: =IF(2>=Usage!$B$18,ROUND(Assumptions!B48*Assumptions!$C$20,0),0) -> 0 | D17: =IF(3>=Usage!$B$18,ROUND(Assumptions!B49*Assumptions!$C$20,0),0) -> 0 | E17: =IF(4>=Usage!$B$18,ROUND(Assumptions!B50*Assumptions!$C$20,0),0) -> 0 | F17: =IF(5>=Usage!$B$18,ROUND(Assumptions!B51*Assumptions!$C$20,0),0) -> 0 | G17: =IF(6>=Usage!$B$18,ROUND(Assumptions!B52*Assumptions!$C$20,0),0) -> 0 | H17: =IF(7>=Usage!$B$18,ROUND(Assumptions!B53*Assumptions!$C$20,0),0) -> 0 | I17: =IF(8>=Usage!$B$18,ROUND(Assumptions!B54*Assumptions!$C$20,0),0) -> 0 | J17: =IF(9>=Usage!$B$18,ROUND(Assumptions!B55*Assumptions!$C$20,0),0) -> 0 | K17: =IF(10>=Usage!$B$18,ROUND(Assumptions!B56*Assumptions!$C$20,0),0) -> 0 | L17: =IF(11>=Usage!$B$18,ROUND(Assumptions!B57*Assumptions!$C$20,0),0) -> 0 | M17: =IF(12>=Usage!$B$18,ROUND(Assumptions!B58*Assumptions!$C$20,0),0) -> 0 | N17: =IF(13>=Usage!$B$18,ROUND(Assumptions!B59*Assumptions!$C$20,0),0) -> 0 | O17: =IF(14>=Usage!$B$18,ROUND(Assumptions!B60*Assumptions!$C$20,0),0) -> 0 | P17: =IF(15>=Usage!$B$18,ROUND(Assumptions!B61*Assumptions!$C$20,0),0) -> 0 | Q17: =IF(16>=Usage!$B$18,ROUND(Assumptions!B62*Assumptions!$C$20,0),0) -> 0 | R17: =IF(17>=Usage!$B$18,ROUND(Assumptions!B63*Assumptions!$C$20,0),0) -> 0 | S17: =IF(18>=Usage!$B$18,ROUND(Assumptions!B64*Assumptions!$C$20,0),0) -> 0 | T17: =IF(19>=Usage!$B$18,ROUND(Assumptions!B65*Assumptions!$C$20,0),0) -> 300 | U17: =IF(20>=Usage!$B$18,ROUND(Assumptions!B66*Assumptions!$C$20,0),0) -> 300 | V17: =IF(21>=Usage!$B$18,ROUND(Assumptions!B67*Assumptions!$C$20,0),0) -> 300 | W17: =IF(22>=Usage!$B$18,ROUND(Assumptions!B68*Assumptions!$C$20,0),0) -> 600 | X17: =IF(23>=Usage!$B$18,ROUND(Assumptions!B69*Assumptions!$C$20,0),0) -> 600 | Y17: =IF(24>=Usage!$B$18,ROUND(Assumptions!B70*Assumptions!$C$20,0),0) -> 600 | Z17: =SUM(B17:Y17) -> 2700
A18: 教师平台云算力条件容量 | B18: =IF(1>=Usage!$B$18,ROUND(Assumptions!C47*Assumptions!$C$20,0),0) -> 0 | C18: =IF(2>=Usage!$B$18,ROUND(Assumptions!C48*Assumptions!$C$20,0),0) -> 0 | D18: =IF(3>=Usage!$B$18,ROUND(Assumptions!C49*Assumptions!$C$20,0),0) -> 0 | E18: =IF(4>=Usage!$B$18,ROUND(Assumptions!C50*Assumptions!$C$20,0),0) -> 0 | F18: =IF(5>=Usage!$B$18,ROUND(Assumptions!C51*Assumptions!$C$20,0),0) -> 0 | G18: =IF(6>=Usage!$B$18,ROUND(Assumptions!C52*Assumptions!$C$20,0),0) -> 0 | H18: =IF(7>=Usage!$B$18,ROUND(Assumptions!C53*Assumptions!$C$20,0),0) -> 0 | I18: =IF(8>=Usage!$B$18,ROUND(Assumptions!C54*Assumptions!$C$20,0),0) -> 0 | J18: =IF(9>=Usage!$B$18,ROUND(Assumptions!C55*Assumptions!$C$20,0),0) -> 0 | K18: =IF(10>=Usage!$B$18,ROUND(Assumptions!C56*Assumptions!$C$20,0),0) -> 0 | L18: =IF(11>=Usage!$B$18,ROUND(Assumptions!C57*Assumptions!$C$20,0),0) -> 0 | M18: =IF(12>=Usage!$B$18,ROUND(Assumptions!C58*Assumptions!$C$20,0),0) -> 0 | N18: =IF(13>=Usage!$B$18,ROUND(Assumptions!C59*Assumptions!$C$20,0),0) -> 0 | O18: =IF(14>=Usage!$B$18,ROUND(Assumptions!C60*Assumptions!$C$20,0),0) -> 0 | P18: =IF(15>=Usage!$B$18,ROUND(Assumptions!C61*Assumptions!$C$20,0),0) -> 0 | Q18: =IF(16>=Usage!$B$18,ROUND(Assumptions!C62*Assumptions!$C$20,0),0) -> 0 | R18: =IF(17>=Usage!$B$18,ROUND(Assumptions!C63*Assumptions!$C$20,0),0) -> 0 | S18: =IF(18>=Usage!$B$18,ROUND(Assumptions!C64*Assumptions!$C$20,0),0) -> 0 | T18: =IF(19>=Usage!$B$18,ROUND(Assumptions!C65*Assumptions!$C$20,0),0) -> 40 | U18: =IF(20>=Usage!$B$18,ROUND(Assumptions!C66*Assumptions!$C$20,0),0) -> 40 | V18: =IF(21>=Usage!$B$18,ROUND(Assumptions!C67*Assumptions!$C$20,0),0) -> 40 | W18: =IF(22>=Usage!$B$18,ROUND(Assumptions!C68*Assumptions!$C$20,0),0) -> 60 | X18: =IF(23>=Usage!$B$18,ROUND(Assumptions!C69*Assumptions!$C$20,0),0) -> 60 | Y18: =IF(24>=Usage!$B$18,ROUND(Assumptions!C70*Assumptions!$C$20,0),0) -> 60 | Z18: =SUM(B18:Y18) -> 300
A19: 专业创作者平台云算力条件容量 | B19: =IF(1>=Usage!$B$18,ROUND(Assumptions!D47*Assumptions!$C$20,0),0) -> 0 | C19: =IF(2>=Usage!$B$18,ROUND(Assumptions!D48*Assumptions!$C$20,0),0) -> 0 | D19: =IF(3>=Usage!$B$18,ROUND(Assumptions!D49*Assumptions!$C$20,0),0) -> 0 | E19: =IF(4>=Usage!$B$18,ROUND(Assumptions!D50*Assumptions!$C$20,0),0) -> 0 | F19: =IF(5>=Usage!$B$18,ROUND(Assumptions!D51*Assumptions!$C$20,0),0) -> 0 | G19: =IF(6>=Usage!$B$18,ROUND(Assumptions!D52*Assumptions!$C$20,0),0) -> 0 | H19: =IF(7>=Usage!$B$18,ROUND(Assumptions!D53*Assumptions!$C$20,0),0) -> 0 | I19: =IF(8>=Usage!$B$18,ROUND(Assumptions!D54*Assumptions!$C$20,0),0) -> 0 | J19: =IF(9>=Usage!$B$18,ROUND(Assumptions!D55*Assumptions!$C$20,0),0) -> 0 | K19: =IF(10>=Usage!$B$18,ROUND(Assumptions!D56*Assumptions!$C$20,0),0) -> 0 | L19: =IF(11>=Usage!$B$18,ROUND(Assumptions!D57*Assumptions!$C$20,0),0) -> 0 | M19: =IF(12>=Usage!$B$18,ROUND(Assumptions!D58*Assumptions!$C$20,0),0) -> 0 | N19: =IF(13>=Usage!$B$18,ROUND(Assumptions!D59*Assumptions!$C$20,0),0) -> 0 | O19: =IF(14>=Usage!$B$18,ROUND(Assumptions!D60*Assumptions!$C$20,0),0) -> 0 | P19: =IF(15>=Usage!$B$18,ROUND(Assumptions!D61*Assumptions!$C$20,0),0) -> 0 | Q19: =IF(16>=Usage!$B$18,ROUND(Assumptions!D62*Assumptions!$C$20,0),0) -> 0 | R19: =IF(17>=Usage!$B$18,ROUND(Assumptions!D63*Assumptions!$C$20,0),0) -> 0 | S19: =IF(18>=Usage!$B$18,ROUND(Assumptions!D64*Assumptions!$C$20,0),0) -> 0 | T19: =IF(19>=Usage!$B$18,ROUND(Assumptions!D65*Assumptions!$C$20,0),0) -> 250 | U19: =IF(20>=Usage!$B$18,ROUND(Assumptions!D66*Assumptions!$C$20,0),0) -> 250 | V19: =IF(21>=Usage!$B$18,ROUND(Assumptions!D67*Assumptions!$C$20,0),0) -> 250 | W19: =IF(22>=Usage!$B$18,ROUND(Assumptions!D68*Assumptions!$C$20,0),0) -> 500 | X19: =IF(23>=Usage!$B$18,ROUND(Assumptions!D69*Assumptions!$C$20,0),0) -> 500 | Y19: =IF(24>=Usage!$B$18,ROUND(Assumptions!D70*Assumptions!$C$20,0),0) -> 500 | Z19: =SUM(B19:Y19) -> 2250
A20: 合计云算力人头（非下载数） | B20: =SUM(B17:B19) -> 0 | C20: =SUM(C17:C19) -> 0 | D20: =SUM(D17:D19) -> 0 | E20: =SUM(E17:E19) -> 0 | F20: =SUM(F17:F19) -> 0 | G20: =SUM(G17:G19) -> 0 | H20: =SUM(H17:H19) -> 0 | I20: =SUM(I17:I19) -> 0 | ... Y20: =SUM(Y17:Y19) -> 1160 | Z20: =Y20 -> 1160
A21: 学生月度算力采购 | B21: =B17*Assumptions!$B$29*Assumptions!$C$21 -> 0 | C21: =C17*Assumptions!$B$29*Assumptions!$C$21 -> 0 | D21: =D17*Assumptions!$B$29*Assumptions!$C$21 -> 0 | E21: =E17*Assumptions!$B$29*Assumptions!$C$21 -> 0 | F21: =F17*Assumptions!$B$29*Assumptions!$C$21 -> 0 | G21: =G17*Assumptions!$B$29*Assumptions!$C$21 -> 0 | H21: =H17*Assumptions!$B$29*Assumptions!$C$21 -> 0 | I21: =I17*Assumptions!$B$29*Assumptions!$C$21 -> 0 | ... Y21: =Y17*Assumptions!$B$29*Assumptions!$C$21 -> 2031.6744 | Z21: =SUM(B21:Y21) -> 9142.5348
A22: 教师月度算力采购 | B22: =B18*Assumptions!$B$30*Assumptions!$C$21 -> 0 | C22: =C18*Assumptions!$B$30*Assumptions!$C$21 -> 0 | D22: =D18*Assumptions!$B$30*Assumptions!$C$21 -> 0 | E22: =E18*Assumptions!$B$30*Assumptions!$C$21 -> 0 | F22: =F18*Assumptions!$B$30*Assumptions!$C$21 -> 0 | G22: =G18*Assumptions!$B$30*Assumptions!$C$21 -> 0 | H22: =H18*Assumptions!$B$30*Assumptions!$C$21 -> 0 | I22: =I18*Assumptions!$B$30*Assumptions!$C$21 -> 0 | ... Y22: =Y18*Assumptions!$B$30*Assumptions!$C$21 -> 1219.0046 | Z22: =SUM(B22:Y22) -> 6095.0232
A23: 个人月度算力采购 | B23: =B19*Assumptions!$B$31*Assumptions!$C$21 -> 0 | C23: =C19*Assumptions!$B$31*Assumptions!$C$21 -> 0 | D23: =D19*Assumptions!$B$31*Assumptions!$C$21 -> 0 | E23: =E19*Assumptions!$B$31*Assumptions!$C$21 -> 0 | F23: =F19*Assumptions!$B$31*Assumptions!$C$21 -> 0 | G23: =G19*Assumptions!$B$31*Assumptions!$C$21 -> 0 | H23: =H19*Assumptions!$B$31*Assumptions!$C$21 -> 0 | I23: =I19*Assumptions!$B$31*Assumptions!$C$21 -> 0 | ... Y23: =Y19*Assumptions!$B$31*Assumptions!$C$21 -> 673510 | Z23: =SUM(B23:Y23) -> 3030795
A24: 外部用户Token成本合计 | B24: =SUM(B21:B23) -> 0 | C24: =SUM(C21:C23) -> 0 | D24: =SUM(D21:D23) -> 0 | E24: =SUM(E21:E23) -> 0 | F24: =SUM(F21:F23) -> 0 | G24: =SUM(G21:G23) -> 0 | H24: =SUM(H21:H23) -> 0 | I24: =SUM(I21:I23) -> 0 | ... Y24: =SUM(Y21:Y23) -> 676760.68 | Z24: =SUM(B24:Y24) -> 3046032.6
A29: 高用量压力
A30: 月份 | B30: =EDATE(Assumptions!$B$3,0) -> 46327 | C30: =EDATE(Assumptions!$B$3,1) -> 46357 | D30: =EDATE(Assumptions!$B$3,2) -> 46388 | E30: =EDATE(Assumptions!$B$3,3) -> 46419 | F30: =EDATE(Assumptions!$B$3,4) -> 46447 | G30: =EDATE(Assumptions!$B$3,5) -> 46478 | H30: =EDATE(Assumptions!$B$3,6) -> 46508 | I30: =EDATE(Assumptions!$B$3,7) -> 46539 | J30: =EDATE(Assumptions!$B$3,8) -> 46569 | K30: =EDATE(Assumptions!$B$3,9) -> 46600 | L30: =EDATE(Assumptions!$B$3,10) -> 46631 | M30: =EDATE(Assumptions!$B$3,11) -> 46661 | N30: =EDATE(Assumptions!$B$3,12) -> 46692 | O30: =EDATE(Assumptions!$B$3,13) -> 46722 | P30: =EDATE(Assumptions!$B$3,14) -> 46753 | Q30: =EDATE(Assumptions!$B$3,15) -> 46784 | R30: =EDATE(Assumptions!$B$3,16) -> 46813 | S30: =EDATE(Assumptions!$B$3,17) -> 46844 | T30: =EDATE(Assumptions!$B$3,18) -> 46874 | U30: =EDATE(Assumptions!$B$3,19) -> 46905 | V30: =EDATE(Assumptions!$B$3,20) -> 46935 | W30: =EDATE(Assumptions!$B$3,21) -> 46966 | X30: =EDATE(Assumptions!$B$3,22) -> 46997 | Y30: =EDATE(Assumptions!$B$3,23) -> 47027 | Z30: 24个月合计 / 期末
A31: 学生平台云算力条件容量 | B31: =IF(1>=Usage!$B$18,ROUND(Assumptions!B47*Assumptions!$D$20,0),0) -> 0 | C31: =IF(2>=Usage!$B$18,ROUND(Assumptions!B48*Assumptions!$D$20,0),0) -> 0 | D31: =IF(3>=Usage!$B$18,ROUND(Assumptions!B49*Assumptions!$D$20,0),0) -> 0 | E31: =IF(4>=Usage!$B$18,ROUND(Assumptions!B50*Assumptions!$D$20,0),0) -> 0 | F31: =IF(5>=Usage!$B$18,ROUND(Assumptions!B51*Assumptions!$D$20,0),0) -> 0 | G31: =IF(6>=Usage!$B$18,ROUND(Assumptions!B52*Assumptions!$D$20,0),0) -> 0 | H31: =IF(7>=Usage!$B$18,ROUND(Assumptions!B53*Assumptions!$D$20,0),0) -> 0 | I31: =IF(8>=Usage!$B$18,ROUND(Assumptions!B54*Assumptions!$D$20,0),0) -> 0 | J31: =IF(9>=Usage!$B$18,ROUND(Assumptions!B55*Assumptions!$D$20,0),0) -> 0 | K31: =IF(10>=Usage!$B$18,ROUND(Assumptions!B56*Assumptions!$D$20,0),0) -> 0 | L31: =IF(11>=Usage!$B$18,ROUND(Assumptions!B57*Assumptions!$D$20,0),0) -> 0 | M31: =IF(12>=Usage!$B$18,ROUND(Assumptions!B58*Assumptions!$D$20,0),0) -> 0 | N31: =IF(13>=Usage!$B$18,ROUND(Assumptions!B59*Assumptions!$D$20,0),0) -> 0 | O31: =IF(14>=Usage!$B$18,ROUND(Assumptions!B60*Assumptions!$D$20,0),0) -> 0 | P31: =IF(15>=Usage!$B$18,ROUND(Assumptions!B61*Assumptions!$D$20,0),0) -> 0 | Q31: =IF(16>=Usage!$B$18,ROUND(Assumptions!B62*Assumptions!$D$20,0),0) -> 0 | R31: =IF(17>=Usage!$B$18,ROUND(Assumptions!B63*Assumptions!$D$20,0),0) -> 0 | S31: =IF(18>=Usage!$B$18,ROUND(Assumptions!B64*Assumptions!$D$20,0),0) -> 0 | T31: =IF(19>=Usage!$B$18,ROUND(Assumptions!B65*Assumptions!$D$20,0),0) -> 600 | U31: =IF(20>=Usage!$B$18,ROUND(Assumptions!B66*Assumptions!$D$20,0),0) -> 600 | V31: =IF(21>=Usage!$B$18,ROUND(Assumptions!B67*Assumptions!$D$20,0),0) -> 600 | W31: =IF(22>=Usage!$B$18,ROUND(Assumptions!B68*Assumptions!$D$20,0),0) -> 1200 | X31: =IF(23>=Usage!$B$18,ROUND(Assumptions!B69*Assumptions!$D$20,0),0) -> 1200 | Y31: =IF(24>=Usage!$B$18,ROUND(Assumptions!B70*Assumptions!$D$20,0),0) -> 1200 | Z31: =SUM(B31:Y31) -> 5400
A32: 教师平台云算力条件容量 | B32: =IF(1>=Usage!$B$18,ROUND(Assumptions!C47*Assumptions!$D$20,0),0) -> 0 | C32: =IF(2>=Usage!$B$18,ROUND(Assumptions!C48*Assumptions!$D$20,0),0) -> 0 | D32: =IF(3>=Usage!$B$18,ROUND(Assumptions!C49*Assumptions!$D$20,0),0) -> 0 | E32: =IF(4>=Usage!$B$18,ROUND(Assumptions!C50*Assumptions!$D$20,0),0) -> 0 | F32: =IF(5>=Usage!$B$18,ROUND(Assumptions!C51*Assumptions!$D$20,0),0) -> 0 | G32: =IF(6>=Usage!$B$18,ROUND(Assumptions!C52*Assumptions!$D$20,0),0) -> 0 | H32: =IF(7>=Usage!$B$18,ROUND(Assumptions!C53*Assumptions!$D$20,0),0) -> 0 | I32: =IF(8>=Usage!$B$18,ROUND(Assumptions!C54*Assumptions!$D$20,0),0) -> 0 | J32: =IF(9>=Usage!$B$18,ROUND(Assumptions!C55*Assumptions!$D$20,0),0) -> 0 | K32: =IF(10>=Usage!$B$18,ROUND(Assumptions!C56*Assumptions!$D$20,0),0) -> 0 | L32: =IF(11>=Usage!$B$18,ROUND(Assumptions!C57*Assumptions!$D$20,0),0) -> 0 | M32: =IF(12>=Usage!$B$18,ROUND(Assumptions!C58*Assumptions!$D$20,0),0) -> 0 | N32: =IF(13>=Usage!$B$18,ROUND(Assumptions!C59*Assumptions!$D$20,0),0) -> 0 | O32: =IF(14>=Usage!$B$18,ROUND(Assumptions!C60*Assumptions!$D$20,0),0) -> 0 | P32: =IF(15>=Usage!$B$18,ROUND(Assumptions!C61*Assumptions!$D$20,0),0) -> 0 | Q32: =IF(16>=Usage!$B$18,ROUND(Assumptions!C62*Assumptions!$D$20,0),0) -> 0 | R32: =IF(17>=Usage!$B$18,ROUND(Assumptions!C63*Assumptions!$D$20,0),0) -> 0 | S32: =IF(18>=Usage!$B$18,ROUND(Assumptions!C64*Assumptions!$D$20,0),0) -> 0 | T32: =IF(19>=Usage!$B$18,ROUND(Assumptions!C65*Assumptions!$D$20,0),0) -> 80 | U32: =IF(20>=Usage!$B$18,ROUND(Assumptions!C66*Assumptions!$D$20,0),0) -> 80 | V32: =IF(21>=Usage!$B$18,ROUND(Assumptions!C67*Assumptions!$D$20,0),0) -> 80 | W32: =IF(22>=Usage!$B$18,ROUND(Assumptions!C68*Assumptions!$D$20,0),0) -> 120 | X32: =IF(23>=Usage!$B$18,ROUND(Assumptions!C69*Assumptions!$D$20,0),0) -> 120 | Y32: =IF(24>=Usage!$B$18,ROUND(Assumptions!C70*Assumptions!$D$20,0),0) -> 120 | Z32: =SUM(B32:Y32) -> 600
A33: 专业创作者平台云算力条件容量 | B33: =IF(1>=Usage!$B$18,ROUND(Assumptions!D47*Assumptions!$D$20,0),0) -> 0 | C33: =IF(2>=Usage!$B$18,ROUND(Assumptions!D48*Assumptions!$D$20,0),0) -> 0 | D33: =IF(3>=Usage!$B$18,ROUND(Assumptions!D49*Assumptions!$D$20,0),0) -> 0 | E33: =IF(4>=Usage!$B$18,ROUND(Assumptions!D50*Assumptions!$D$20,0),0) -> 0 | F33: =IF(5>=Usage!$B$18,ROUND(Assumptions!D51*Assumptions!$D$20,0),0) -> 0 | G33: =IF(6>=Usage!$B$18,ROUND(Assumptions!D52*Assumptions!$D$20,0),0) -> 0 | H33: =IF(7>=Usage!$B$18,ROUND(Assumptions!D53*Assumptions!$D$20,0),0) -> 0 | I33: =IF(8>=Usage!$B$18,ROUND(Assumptions!D54*Assumptions!$D$20,0),0) -> 0 | J33: =IF(9>=Usage!$B$18,ROUND(Assumptions!D55*Assumptions!$D$20,0),0) -> 0 | K33: =IF(10>=Usage!$B$18,ROUND(Assumptions!D56*Assumptions!$D$20,0),0) -> 0 | L33: =IF(11>=Usage!$B$18,ROUND(Assumptions!D57*Assumptions!$D$20,0),0) -> 0 | M33: =IF(12>=Usage!$B$18,ROUND(Assumptions!D58*Assumptions!$D$20,0),0) -> 0 | N33: =IF(13>=Usage!$B$18,ROUND(Assumptions!D59*Assumptions!$D$20,0),0) -> 0 | O33: =IF(14>=Usage!$B$18,ROUND(Assumptions!D60*Assumptions!$D$20,0),0) -> 0 | P33: =IF(15>=Usage!$B$18,ROUND(Assumptions!D61*Assumptions!$D$20,0),0) -> 0 | Q33: =IF(16>=Usage!$B$18,ROUND(Assumptions!D62*Assumptions!$D$20,0),0) -> 0 | R33: =IF(17>=Usage!$B$18,ROUND(Assumptions!D63*Assumptions!$D$20,0),0) -> 0 | S33: =IF(18>=Usage!$B$18,ROUND(Assumptions!D64*Assumptions!$D$20,0),0) -> 0 | T33: =IF(19>=Usage!$B$18,ROUND(Assumptions!D65*Assumptions!$D$20,0),0) -> 500 | U33: =IF(20>=Usage!$B$18,ROUND(Assumptions!D66*Assumptions!$D$20,0),0) -> 500 | V33: =IF(21>=Usage!$B$18,ROUND(Assumptions!D67*Assumptions!$D$20,0),0) -> 500 | W33: =IF(22>=Usage!$B$18,ROUND(Assumptions!D68*Assumptions!$D$20,0),0) -> 1000 | X33: =IF(23>=Usage!$B$18,ROUND(Assumptions!D69*Assumptions!$D$20,0),0) -> 1000 | Y33: =IF(24>=Usage!$B$18,ROUND(Assumptions!D70*Assumptions!$D$20,0),0) -> 1000 | Z33: =SUM(B33:Y33) -> 4500
A34: 合计云算力人头（非下载数） | B34: =SUM(B31:B33) -> 0 | C34: =SUM(C31:C33) -> 0 | D34: =SUM(D31:D33) -> 0 | E34: =SUM(E31:E33) -> 0 | F34: =SUM(F31:F33) -> 0 | G34: =SUM(G31:G33) -> 0 | H34: =SUM(H31:H33) -> 0 | I34: =SUM(I31:I33) -> 0 | ... Y34: =SUM(Y31:Y33) -> 2320 | Z34: =Y34 -> 2320
A35: 学生月度算力采购 | B35: =B31*Assumptions!$B$29*Assumptions!$D$21 -> 0 | C35: =C31*Assumptions!$B$29*Assumptions!$D$21 -> 0 | D35: =D31*Assumptions!$B$29*Assumptions!$D$21 -> 0 | E35: =E31*Assumptions!$B$29*Assumptions!$D$21 -> 0 | F35: =F31*Assumptions!$B$29*Assumptions!$D$21 -> 0 | G35: =G31*Assumptions!$B$29*Assumptions!$D$21 -> 0 | H35: =H31*Assumptions!$B$29*Assumptions!$D$21 -> 0 | I35: =I31*Assumptions!$B$29*Assumptions!$D$21 -> 0 | ... Y35: =Y31*Assumptions!$B$29*Assumptions!$D$21 -> 10158.372 | Z35: =SUM(B35:Y35) -> 45712.674
A36: 教师月度算力采购 | B36: =B32*Assumptions!$B$30*Assumptions!$D$21 -> 0 | C36: =C32*Assumptions!$B$30*Assumptions!$D$21 -> 0 | D36: =D32*Assumptions!$B$30*Assumptions!$D$21 -> 0 | E36: =E32*Assumptions!$B$30*Assumptions!$D$21 -> 0 | F36: =F32*Assumptions!$B$30*Assumptions!$D$21 -> 0 | G36: =G32*Assumptions!$B$30*Assumptions!$D$21 -> 0 | H36: =H32*Assumptions!$B$30*Assumptions!$D$21 -> 0 | I36: =I32*Assumptions!$B$30*Assumptions!$D$21 -> 0 | ... Y36: =Y32*Assumptions!$B$30*Assumptions!$D$21 -> 6095.0232 | Z36: =SUM(B36:Y36) -> 30475.116
A37: 个人月度算力采购 | B37: =B33*Assumptions!$B$31*Assumptions!$D$21 -> 0 | C37: =C33*Assumptions!$B$31*Assumptions!$D$21 -> 0 | D37: =D33*Assumptions!$B$31*Assumptions!$D$21 -> 0 | E37: =E33*Assumptions!$B$31*Assumptions!$D$21 -> 0 | F37: =F33*Assumptions!$B$31*Assumptions!$D$21 -> 0 | G37: =G33*Assumptions!$B$31*Assumptions!$D$21 -> 0 | H37: =H33*Assumptions!$B$31*Assumptions!$D$21 -> 0 | I37: =I33*Assumptions!$B$31*Assumptions!$D$21 -> 0 | ... Y37: =Y33*Assumptions!$B$31*Assumptions!$D$21 -> 3367550 | Z37: =SUM(B37:Y37) -> 15153975
A38: 外部用户Token成本合计 | B38: =SUM(B35:B37) -> 0 | C38: =SUM(C35:C37) -> 0 | D38: =SUM(D35:D37) -> 0 | E38: =SUM(E35:E37) -> 0 | F38: =SUM(F35:F37) -> 0 | G38: =SUM(G35:G37) -> 0 | H38: =SUM(H35:H37) -> 0 | I38: =SUM(I35:I37) -> 0 | ... Y38: =SUM(Y35:Y37) -> 3383803.4 | Z38: =SUM(B38:Y38) -> 15230163

Sheet Costs
A1: 精简推进
A2: 月份 | B2: =EDATE(Assumptions!$B$3,0) -> 46327 | C2: =EDATE(Assumptions!$B$3,1) -> 46357 | D2: =EDATE(Assumptions!$B$3,2) -> 46388 | E2: =EDATE(Assumptions!$B$3,3) -> 46419 | F2: =EDATE(Assumptions!$B$3,4) -> 46447 | G2: =EDATE(Assumptions!$B$3,5) -> 46478 | H2: =EDATE(Assumptions!$B$3,6) -> 46508 | I2: =EDATE(Assumptions!$B$3,7) -> 46539 | J2: =EDATE(Assumptions!$B$3,8) -> 46569 | K2: =EDATE(Assumptions!$B$3,9) -> 46600 | L2: =EDATE(Assumptions!$B$3,10) -> 46631 | M2: =EDATE(Assumptions!$B$3,11) -> 46661 | N2: =EDATE(Assumptions!$B$3,12) -> 46692 | O2: =EDATE(Assumptions!$B$3,13) -> 46722 | P2: =EDATE(Assumptions!$B$3,14) -> 46753 | Q2: =EDATE(Assumptions!$B$3,15) -> 46784 | R2: =EDATE(Assumptions!$B$3,16) -> 46813 | S2: =EDATE(Assumptions!$B$3,17) -> 46844 | T2: =EDATE(Assumptions!$B$3,18) -> 46874 | U2: =EDATE(Assumptions!$B$3,19) -> 46905 | V2: =EDATE(Assumptions!$B$3,20) -> 46935 | W2: =EDATE(Assumptions!$B$3,21) -> 46966 | X2: =EDATE(Assumptions!$B$3,22) -> 46997 | Y2: =EDATE(Assumptions!$B$3,23) -> 47027 | Z2: 24个月合计 / 期末
A3: 等效资源人力 | B3: =IF(1<=6,Assumptions!$B$17,Assumptions!$B$18) -> 2 | C3: =IF(2<=6,Assumptions!$B$17,Assumptions!$B$18) -> 2 | D3: =IF(3<=6,Assumptions!$B$17,Assumptions!$B$18) -> 2 | E3: =IF(4<=6,Assumptions!$B$17,Assumptions!$B$18) -> 2 | F3: =IF(5<=6,Assumptions!$B$17,Assumptions!$B$18) -> 2 | G3: =IF(6<=6,Assumptions!$B$17,Assumptions!$B$18) -> 2 | H3: =IF(7<=6,Assumptions!$B$17,Assumptions!$B$18) -> 3 | I3: =IF(8<=6,Assumptions!$B$17,Assumptions!$B$18) -> 3 | J3: =IF(9<=6,Assumptions!$B$17,Assumptions!$B$18) -> 3 | K3: =IF(10<=6,Assumptions!$B$17,Assumptions!$B$18) -> 3 | L3: =IF(11<=6,Assumptions!$B$17,Assumptions!$B$18) -> 3 | M3: =IF(12<=6,Assumptions!$B$17,Assumptions!$B$18) -> 3 | N3: =IF(13<=6,Assumptions!$B$17,Assumptions!$B$18) -> 3 | O3: =IF(14<=6,Assumptions!$B$17,Assumptions!$B$18) -> 3 | P3: =IF(15<=6,Assumptions!$B$17,Assumptions!$B$18) -> 3 | Q3: =IF(16<=6,Assumptions!$B$17,Assumptions!$B$18) -> 3 | R3: =IF(17<=6,Assumptions!$B$17,Assumptions!$B$18) -> 3 | S3: =IF(18<=6,Assumptions!$B$17,Assumptions!$B$18) -> 3 | T3: =IF(19<=6,Assumptions!$B$17,Assumptions!$B$18) -> 3 | U3: =IF(20<=6,Assumptions!$B$17,Assumptions!$B$18) -> 3 | V3: =IF(21<=6,Assumptions!$B$17,Assumptions!$B$18) -> 3 | W3: =IF(22<=6,Assumptions!$B$17,Assumptions!$B$18) -> 3 | X3: =IF(23<=6,Assumptions!$B$17,Assumptions!$B$18) -> 3 | Y3: =IF(24<=6,Assumptions!$B$17,Assumptions!$B$18) -> 3 | Z3: =SUM(B3:Y3) -> 66
A4: 综合人力现金 | B4: =B3*Assumptions!$B$19 -> 32000 | C4: =C3*Assumptions!$B$19 -> 32000 | D4: =D3*Assumptions!$B$19 -> 32000 | E4: =E3*Assumptions!$B$19 -> 32000 | F4: =F3*Assumptions!$B$19 -> 32000 | G4: =G3*Assumptions!$B$19 -> 32000 | H4: =H3*Assumptions!$B$19 -> 48000 | I4: =I3*Assumptions!$B$19 -> 48000 | ... Y4: =Y3*Assumptions!$B$19 -> 48000 | Z4: =SUM(B4:Y4) -> 1056000
A5: 内部研发Agent预算 | B5: =B3*Assumptions!$B$32*Assumptions!$B$22 -> 2889.3579 | C5: =C3*Assumptions!$B$32*Assumptions!$B$22 -> 2889.3579 | D5: =D3*Assumptions!$B$32*Assumptions!$B$22 -> 2889.3579 | E5: =E3*Assumptions!$B$32*Assumptions!$B$22 -> 2889.3579 | F5: =F3*Assumptions!$B$32*Assumptions!$B$22 -> 2889.3579 | G5: =G3*Assumptions!$B$32*Assumptions!$B$22 -> 2889.3579 | H5: =H3*Assumptions!$B$32*Assumptions!$B$22 -> 4334.0369 | I5: =I3*Assumptions!$B$32*Assumptions!$B$22 -> 4334.0369 | ... Y5: =Y3*Assumptions!$B$32*Assumptions!$B$22 -> 4334.0369 | Z5: =SUM(B5:Y5) -> 95348.811
A6: 云基础设施 | B6: =IF(1<=6,Assumptions!$B$34,IF(1<=12,Assumptions!$B$35,Assumptions!$B$36))*Assumptions!$B$22 -> 2250 | C6: =IF(2<=6,Assumptions!$B$34,IF(2<=12,Assumptions!$B$35,Assumptions!$B$36))*Assumptions!$B$22 -> 2250 | D6: =IF(3<=6,Assumptions!$B$34,IF(3<=12,Assumptions!$B$35,Assumptions!$B$36))*Assumptions!$B$22 -> 2250 | E6: =IF(4<=6,Assumptions!$B$34,IF(4<=12,Assumptions!$B$35,Assumptions!$B$36))*Assumptions!$B$22 -> 2250 | F6: =IF(5<=6,Assumptions!$B$34,IF(5<=12,Assumptions!$B$35,Assumptions!$B$36))*Assumptions!$B$22 -> 2250 | G6: =IF(6<=6,Assumptions!$B$34,IF(6<=12,Assumptions!$B$35,Assumptions!$B$36))*Assumptions!$B$22 -> 2250 | H6: =IF(7<=6,Assumptions!$B$34,IF(7<=12,Assumptions!$B$35,Assumptions!$B$36))*Assumptions!$B$22 -> 4500 | I6: =IF(8<=6,Assumptions!$B$34,IF(8<=12,Assumptions!$B$35,Assumptions!$B$36))*Assumptions!$B$22 -> 4500 | J6: =IF(9<=6,Assumptions!$B$34,IF(9<=12,Assumptions!$B$35,Assumptions!$B$36))*Assumptions!$B$22 -> 4500 | K6: =IF(10<=6,Assumptions!$B$34,IF(10<=12,Assumptions!$B$35,Assumptions!$B$36))*Assumptions!$B$22 -> 4500 | L6: =IF(11<=6,Assumptions!$B$34,IF(11<=12,Assumptions!$B$35,Assumptions!$B$36))*Assumptions!$B$22 -> 4500 | M6: =IF(12<=6,Assumptions!$B$34,IF(12<=12,Assumptions!$B$35,Assumptions!$B$36))*Assumptions!$B$22 -> 4500 | N6: =IF(13<=6,Assumptions!$B$34,IF(13<=12,Assumptions!$B$35,Assumptions!$B$36))*Assumptions!$B$22 -> 6750 | O6: =IF(14<=6,Assumptions!$B$34,IF(14<=12,Assumptions!$B$35,Assumptions!$B$36))*Assumptions!$B$22 -> 6750 | P6: =IF(15<=6,Assumptions!$B$34,IF(15<=12,Assumptions!$B$35,Assumptions!$B$36))*Assumptions!$B$22 -> 6750 | Q6: =IF(16<=6,Assumptions!$B$34,IF(16<=12,Assumptions!$B$35,Assumptions!$B$36))*Assumptions!$B$22 -> 6750 | R6: =IF(17<=6,Assumptions!$B$34,IF(17<=12,Assumptions!$B$35,Assumptions!$B$36))*Assumptions!$B$22 -> 6750 | S6: =IF(18<=6,Assumptions!$B$34,IF(18<=12,Assumptions!$B$35,Assumptions!$B$36))*Assumptions!$B$22 -> 6750 | T6: =IF(19<=6,Assumptions!$B$34,IF(19<=12,Assumptions!$B$35,Assumptions!$B$36))*Assumptions!$B$22 -> 6750 | U6: =IF(20<=6,Assumptions!$B$34,IF(20<=12,Assumptions!$B$35,Assumptions!$B$36))*Assumptions!$B$22 -> 6750 | V6: =IF(21<=6,Assumptions!$B$34,IF(21<=12,Assumptions!$B$35,Assumptions!$B$36))*Assumptions!$B$22 -> 6750 | W6: =IF(22<=6,Assumptions!$B$34,IF(22<=12,Assumptions!$B$35,Assumptions!$B$36))*Assumptions!$B$22 -> 6750 | X6: =IF(23<=6,Assumptions!$B$34,IF(23<=12,Assumptions!$B$35,Assumptions!$B$36))*Assumptions!$B$22 -> 6750 | Y6: =IF(24<=6,Assumptions!$B$34,IF(24<=12,Assumptions!$B$35,Assumptions!$B$36))*Assumptions!$B$22 -> 6750 | Z6: =SUM(B6:Y6) -> 121500
A7: 教学共创与试用 | B7: =IF(1<=3,Assumptions!$B$37,IF(1<=12,Assumptions!$B$38,Assumptions!$B$39))*Assumptions!$B$22 -> 0 | C7: =IF(2<=3,Assumptions!$B$37,IF(2<=12,Assumptions!$B$38,Assumptions!$B$39))*Assumptions!$B$22 -> 0 | D7: =IF(3<=3,Assumptions!$B$37,IF(3<=12,Assumptions!$B$38,Assumptions!$B$39))*Assumptions!$B$22 -> 0 | E7: =IF(4<=3,Assumptions!$B$37,IF(4<=12,Assumptions!$B$38,Assumptions!$B$39))*Assumptions!$B$22 -> 4500 | F7: =IF(5<=3,Assumptions!$B$37,IF(5<=12,Assumptions!$B$38,Assumptions!$B$39))*Assumptions!$B$22 -> 4500 | G7: =IF(6<=3,Assumptions!$B$37,IF(6<=12,Assumptions!$B$38,Assumptions!$B$39))*Assumptions!$B$22 -> 4500 | H7: =IF(7<=3,Assumptions!$B$37,IF(7<=12,Assumptions!$B$38,Assumptions!$B$39))*Assumptions!$B$22 -> 4500 | I7: =IF(8<=3,Assumptions!$B$37,IF(8<=12,Assumptions!$B$38,Assumptions!$B$39))*Assumptions!$B$22 -> 4500 | J7: =IF(9<=3,Assumptions!$B$37,IF(9<=12,Assumptions!$B$38,Assumptions!$B$39))*Assumptions!$B$22 -> 4500 | K7: =IF(10<=3,Assumptions!$B$37,IF(10<=12,Assumptions!$B$38,Assumptions!$B$39))*Assumptions!$B$22 -> 4500 | L7: =IF(11<=3,Assumptions!$B$37,IF(11<=12,Assumptions!$B$38,Assumptions!$B$39))*Assumptions!$B$22 -> 4500 | M7: =IF(12<=3,Assumptions!$B$37,IF(12<=12,Assumptions!$B$38,Assumptions!$B$39))*Assumptions!$B$22 -> 4500 | N7: =IF(13<=3,Assumptions!$B$37,IF(13<=12,Assumptions!$B$38,Assumptions!$B$39))*Assumptions!$B$22 -> 6000 | O7: =IF(14<=3,Assumptions!$B$37,IF(14<=12,Assumptions!$B$38,Assumptions!$B$39))*Assumptions!$B$22 -> 6000 | P7: =IF(15<=3,Assumptions!$B$37,IF(15<=12,Assumptions!$B$38,Assumptions!$B$39))*Assumptions!$B$22 -> 6000 | Q7: =IF(16<=3,Assumptions!$B$37,IF(16<=12,Assumptions!$B$38,Assumptions!$B$39))*Assumptions!$B$22 -> 6000 | R7: =IF(17<=3,Assumptions!$B$37,IF(17<=12,Assumptions!$B$38,Assumptions!$B$39))*Assumptions!$B$22 -> 6000 | S7: =IF(18<=3,Assumptions!$B$37,IF(18<=12,Assumptions!$B$38,Assumptions!$B$39))*Assumptions!$B$22 -> 6000 | T7: =IF(19<=3,Assumptions!$B$37,IF(19<=12,Assumptions!$B$38,Assumptions!$B$39))*Assumptions!$B$22 -> 6000 | U7: =IF(20<=3,Assumptions!$B$37,IF(20<=12,Assumptions!$B$38,Assumptions!$B$39))*Assumptions!$B$22 -> 6000 | V7: =IF(21<=3,Assumptions!$B$37,IF(21<=12,Assumptions!$B$38,Assumptions!$B$39))*Assumptions!$B$22 -> 6000 | W7: =IF(22<=3,Assumptions!$B$37,IF(22<=12,Assumptions!$B$38,Assumptions!$B$39))*Assumptions!$B$22 -> 6000 | X7: =IF(23<=3,Assumptions!$B$37,IF(23<=12,Assumptions!$B$38,Assumptions!$B$39))*Assumptions!$B$22 -> 6000 | Y7: =IF(24<=3,Assumptions!$B$37,IF(24<=12,Assumptions!$B$38,Assumptions!$B$39))*Assumptions!$B$22 -> 6000 | Z7: =SUM(B7:Y7) -> 112500
A8: 社区活动与材料 | B8: =IF(1<=3,Assumptions!$B$40,IF(1<=12,Assumptions!$B$41,Assumptions!$B$42))*Assumptions!$B$22 -> 0 | C8: =IF(2<=3,Assumptions!$B$40,IF(2<=12,Assumptions!$B$41,Assumptions!$B$42))*Assumptions!$B$22 -> 0 | D8: =IF(3<=3,Assumptions!$B$40,IF(3<=12,Assumptions!$B$41,Assumptions!$B$42))*Assumptions!$B$22 -> 0 | E8: =IF(4<=3,Assumptions!$B$40,IF(4<=12,Assumptions!$B$41,Assumptions!$B$42))*Assumptions!$B$22 -> 2250 | F8: =IF(5<=3,Assumptions!$B$40,IF(5<=12,Assumptions!$B$41,Assumptions!$B$42))*Assumptions!$B$22 -> 2250 | G8: =IF(6<=3,Assumptions!$B$40,IF(6<=12,Assumptions!$B$41,Assumptions!$B$42))*Assumptions!$B$22 -> 2250 | H8: =IF(7<=3,Assumptions!$B$40,IF(7<=12,Assumptions!$B$41,Assumptions!$B$42))*Assumptions!$B$22 -> 2250 | I8: =IF(8<=3,Assumptions!$B$40,IF(8<=12,Assumptions!$B$41,Assumptions!$B$42))*Assumptions!$B$22 -> 2250 | J8: =IF(9<=3,Assumptions!$B$40,IF(9<=12,Assumptions!$B$41,Assumptions!$B$42))*Assumptions!$B$22 -> 2250 | K8: =IF(10<=3,Assumptions!$B$40,IF(10<=12,Assumptions!$B$41,Assumptions!$B$42))*Assumptions!$B$22 -> 2250 | L8: =IF(11<=3,Assumptions!$B$40,IF(11<=12,Assumptions!$B$41,Assumptions!$B$42))*Assumptions!$B$22 -> 2250 | M8: =IF(12<=3,Assumptions!$B$40,IF(12<=12,Assumptions!$B$41,Assumptions!$B$42))*Assumptions!$B$22 -> 2250 | N8: =IF(13<=3,Assumptions!$B$40,IF(13<=12,Assumptions!$B$41,Assumptions!$B$42))*Assumptions!$B$22 -> 4500 | O8: =IF(14<=3,Assumptions!$B$40,IF(14<=12,Assumptions!$B$41,Assumptions!$B$42))*Assumptions!$B$22 -> 4500 | P8: =IF(15<=3,Assumptions!$B$40,IF(15<=12,Assumptions!$B$41,Assumptions!$B$42))*Assumptions!$B$22 -> 4500 | Q8: =IF(16<=3,Assumptions!$B$40,IF(16<=12,Assumptions!$B$41,Assumptions!$B$42))*Assumptions!$B$22 -> 4500 | R8: =IF(17<=3,Assumptions!$B$40,IF(17<=12,Assumptions!$B$41,Assumptions!$B$42))*Assumptions!$B$22 -> 4500 | S8: =IF(18<=3,Assumptions!$B$40,IF(18<=12,Assumptions!$B$41,Assumptions!$B$42))*Assumptions!$B$22 -> 4500 | T8: =IF(19<=3,Assumptions!$B$40,IF(19<=12,Assumptions!$B$41,Assumptions!$B$42))*Assumptions!$B$22 -> 4500 | U8: =IF(20<=3,Assumptions!$B$40,IF(20<=12,Assumptions!$B$41,Assumptions!$B$42))*Assumptions!$B$22 -> 4500 | V8: =IF(21<=3,Assumptions!$B$40,IF(21<=12,Assumptions!$B$41,Assumptions!$B$42))*Assumptions!$B$22 -> 4500 | W8: =IF(22<=3,Assumptions!$B$40,IF(22<=12,Assumptions!$B$41,Assumptions!$B$42))*Assumptions!$B$22 -> 4500 | X8: =IF(23<=3,Assumptions!$B$40,IF(23<=12,Assumptions!$B$41,Assumptions!$B$42))*Assumptions!$B$22 -> 4500 | Y8: =IF(24<=3,Assumptions!$B$40,IF(24<=12,Assumptions!$B$41,Assumptions!$B$42))*Assumptions!$B$22 -> 4500 | Z8: =SUM(B8:Y8) -> 74250
A9: 一般运营与合规预算 | B9: =Assumptions!$B$43*Assumptions!$B$22 -> 2250 | C9: =Assumptions!$B$43*Assumptions!$B$22 -> 2250 | D9: =Assumptions!$B$43*Assumptions!$B$22 -> 2250 | E9: =Assumptions!$B$43*Assumptions!$B$22 -> 2250 | F9: =Assumptions!$B$43*Assumptions!$B$22 -> 2250 | G9: =Assumptions!$B$43*Assumptions!$B$22 -> 2250 | H9: =Assumptions!$B$43*Assumptions!$B$22 -> 2250 | I9: =Assumptions!$B$43*Assumptions!$B$22 -> 2250 | ... Y9: =Assumptions!$B$43*Assumptions!$B$22 -> 2250 | Z9: =SUM(B9:Y9) -> 54000
A10: 专项外部交付 | B10: =SUMIF(Assumptions!$F$47:$F$50,1,Assumptions!$G$47:$G$50)*Assumptions!$B$22 -> 0 | C10: =SUMIF(Assumptions!$F$47:$F$50,2,Assumptions!$G$47:$G$50)*Assumptions!$B$22 -> 0 | D10: =SUMIF(Assumptions!$F$47:$F$50,3,Assumptions!$G$47:$G$50)*Assumptions!$B$22 -> 0 | E10: =SUMIF(Assumptions!$F$47:$F$50,4,Assumptions!$G$47:$G$50)*Assumptions!$B$22 -> 0 | F10: =SUMIF(Assumptions!$F$47:$F$50,5,Assumptions!$G$47:$G$50)*Assumptions!$B$22 -> 0 | G10: =SUMIF(Assumptions!$F$47:$F$50,6,Assumptions!$G$47:$G$50)*Assumptions!$B$22 -> 22500 | H10: =SUMIF(Assumptions!$F$47:$F$50,7,Assumptions!$G$47:$G$50)*Assumptions!$B$22 -> 0 | I10: =SUMIF(Assumptions!$F$47:$F$50,8,Assumptions!$G$47:$G$50)*Assumptions!$B$22 -> 0 | J10: =SUMIF(Assumptions!$F$47:$F$50,9,Assumptions!$G$47:$G$50)*Assumptions!$B$22 -> 0 | K10: =SUMIF(Assumptions!$F$47:$F$50,10,Assumptions!$G$47:$G$50)*Assumptions!$B$22 -> 0 | L10: =SUMIF(Assumptions!$F$47:$F$50,11,Assumptions!$G$47:$G$50)*Assumptions!$B$22 -> 0 | M10: =SUMIF(Assumptions!$F$47:$F$50,12,Assumptions!$G$47:$G$50)*Assumptions!$B$22 -> 30000 | N10: =SUMIF(Assumptions!$F$47:$F$50,13,Assumptions!$G$47:$G$50)*Assumptions!$B$22 -> 0 | O10: =SUMIF(Assumptions!$F$47:$F$50,14,Assumptions!$G$47:$G$50)*Assumptions!$B$22 -> 0 | P10: =SUMIF(Assumptions!$F$47:$F$50,15,Assumptions!$G$47:$G$50)*Assumptions!$B$22 -> 0 | Q10: =SUMIF(Assumptions!$F$47:$F$50,16,Assumptions!$G$47:$G$50)*Assumptions!$B$22 -> 0 | R10: =SUMIF(Assumptions!$F$47:$F$50,17,Assumptions!$G$47:$G$50)*Assumptions!$B$22 -> 0 | S10: =SUMIF(Assumptions!$F$47:$F$50,18,Assumptions!$G$47:$G$50)*Assumptions!$B$22 -> 30000 | T10: =SUMIF(Assumptions!$F$47:$F$50,19,Assumptions!$G$47:$G$50)*Assumptions!$B$22 -> 0 | U10: =SUMIF(Assumptions!$F$47:$F$50,20,Assumptions!$G$47:$G$50)*Assumptions!$B$22 -> 0 | V10: =SUMIF(Assumptions!$F$47:$F$50,21,Assumptions!$G$47:$G$50)*Assumptions!$B$22 -> 0 | W10: =SUMIF(Assumptions!$F$47:$F$50,22,Assumptions!$G$47:$G$50)*Assumptions!$B$22 -> 0 | X10: =SUMIF(Assumptions!$F$47:$F$50,23,Assumptions!$G$47:$G$50)*Assumptions!$B$22 -> 0 | Y10: =SUMIF(Assumptions!$F$47:$F$50,24,Assumptions!$G$47:$G$50)*Assumptions!$B$22 -> 30000 | Z10: =SUM(B10:Y10) -> 112500
A11: 条件用户算力成本 | B11: =Cohorts!B10 -> 0 | C11: =Cohorts!C10 -> 0 | D11: =Cohorts!D10 -> 0 | E11: =Cohorts!E10 -> 0 | F11: =Cohorts!F10 -> 0 | G11: =Cohorts!G10 -> 0 | H11: =Cohorts!H10 -> 0 | I11: =Cohorts!I10 -> 0 | ... Y11: =Cohorts!Y10 -> 203028.2 | Z11: =SUM(B11:Y11) -> 913809.77
A12: 实际非退还合作费（未录入） | B12: =IF(1=Assumptions!$B$10,Assumptions!$B$7,0) -> 0 | C12: =IF(2=Assumptions!$B$10,Assumptions!$B$7,0) -> 0 | D12: =IF(3=Assumptions!$B$10,Assumptions!$B$7,0) -> 0 | E12: =IF(4=Assumptions!$B$10,Assumptions!$B$7,0) -> 0 | F12: =IF(5=Assumptions!$B$10,Assumptions!$B$7,0) -> 0 | G12: =IF(6=Assumptions!$B$10,Assumptions!$B$7,0) -> 0 | H12: =IF(7=Assumptions!$B$10,Assumptions!$B$7,0) -> 0 | I12: =IF(8=Assumptions!$B$10,Assumptions!$B$7,0) -> 0 | J12: =IF(9=Assumptions!$B$10,Assumptions!$B$7,0) -> 0 | K12: =IF(10=Assumptions!$B$10,Assumptions!$B$7,0) -> 0 | L12: =IF(11=Assumptions!$B$10,Assumptions!$B$7,0) -> 0 | M12: =IF(12=Assumptions!$B$10,Assumptions!$B$7,0) -> 0 | N12: =IF(13=Assumptions!$B$10,Assumptions!$B$7,0) -> 0 | O12: =IF(14=Assumptions!$B$10,Assumptions!$B$7,0) -> 0 | P12: =IF(15=Assumptions!$B$10,Assumptions!$B$7,0) -> 0 | Q12: =IF(16=Assumptions!$B$10,Assumptions!$B$7,0) -> 0 | R12: =IF(17=Assumptions!$B$10,Assumptions!$B$7,0) -> 0 | S12: =IF(18=Assumptions!$B$10,Assumptions!$B$7,0) -> 0 | T12: =IF(19=Assumptions!$B$10,Assumptions!$B$7,0) -> 0 | U12: =IF(20=Assumptions!$B$10,Assumptions!$B$7,0) -> 0 | V12: =IF(21=Assumptions!$B$10,Assumptions!$B$7,0) -> 0 | W12: =IF(22=Assumptions!$B$10,Assumptions!$B$7,0) -> 0 | X12: =IF(23=Assumptions!$B$10,Assumptions!$B$7,0) -> 0 | Y12: =IF(24=Assumptions!$B$10,Assumptions!$B$7,0) -> 0 | Z12: =SUM(B12:Y12) -> 0
A13: 费用现金合计（不含设备） | B13: =SUM(B4:B12) -> 39389.358 | C13: =SUM(C4:C12) -> 39389.358 | D13: =SUM(D4:D12) -> 39389.358 | E13: =SUM(E4:E12) -> 46139.358 | F13: =SUM(F4:F12) -> 46139.358 | G13: =SUM(G4:G12) -> 68639.358 | H13: =SUM(H4:H12) -> 65834.037 | I13: =SUM(I4:I12) -> 65834.037 | ... Y13: =SUM(Y4:Y12) -> 304862.24 | Z13: =SUM(B13:Y13) -> 2539908.6
A14: 设备购置现金 | B14: =SUMIF(Assumptions!$F$54:$F$55,1,Assumptions!$G$54:$G$55)*Assumptions!$B$22 -> 37500 | C14: =SUMIF(Assumptions!$F$54:$F$55,2,Assumptions!$G$54:$G$55)*Assumptions!$B$22 -> 0 | D14: =SUMIF(Assumptions!$F$54:$F$55,3,Assumptions!$G$54:$G$55)*Assumptions!$B$22 -> 0 | E14: =SUMIF(Assumptions!$F$54:$F$55,4,Assumptions!$G$54:$G$55)*Assumptions!$B$22 -> 0 | F14: =SUMIF(Assumptions!$F$54:$F$55,5,Assumptions!$G$54:$G$55)*Assumptions!$B$22 -> 0 | G14: =SUMIF(Assumptions!$F$54:$F$55,6,Assumptions!$G$54:$G$55)*Assumptions!$B$22 -> 0 | H14: =SUMIF(Assumptions!$F$54:$F$55,7,Assumptions!$G$54:$G$55)*Assumptions!$B$22 -> 22500 | I14: =SUMIF(Assumptions!$F$54:$F$55,8,Assumptions!$G$54:$G$55)*Assumptions!$B$22 -> 0 | J14: =SUMIF(Assumptions!$F$54:$F$55,9,Assumptions!$G$54:$G$55)*Assumptions!$B$22 -> 0 | K14: =SUMIF(Assumptions!$F$54:$F$55,10,Assumptions!$G$54:$G$55)*Assumptions!$B$22 -> 0 | L14: =SUMIF(Assumptions!$F$54:$F$55,11,Assumptions!$G$54:$G$55)*Assumptions!$B$22 -> 0 | M14: =SUMIF(Assumptions!$F$54:$F$55,12,Assumptions!$G$54:$G$55)*Assumptions!$B$22 -> 0 | N14: =SUMIF(Assumptions!$F$54:$F$55,13,Assumptions!$G$54:$G$55)*Assumptions!$B$22 -> 0 | O14: =SUMIF(Assumptions!$F$54:$F$55,14,Assumptions!$G$54:$G$55)*Assumptions!$B$22 -> 0 | P14: =SUMIF(Assumptions!$F$54:$F$55,15,Assumptions!$G$54:$G$55)*Assumptions!$B$22 -> 0 | Q14: =SUMIF(Assumptions!$F$54:$F$55,16,Assumptions!$G$54:$G$55)*Assumptions!$B$22 -> 0 | R14: =SUMIF(Assumptions!$F$54:$F$55,17,Assumptions!$G$54:$G$55)*Assumptions!$B$22 -> 0 | S14: =SUMIF(Assumptions!$F$54:$F$55,18,Assumptions!$G$54:$G$55)*Assumptions!$B$22 -> 0 | T14: =SUMIF(Assumptions!$F$54:$F$55,19,Assumptions!$G$54:$G$55)*Assumptions!$B$22 -> 0 | U14: =SUMIF(Assumptions!$F$54:$F$55,20,Assumptions!$G$54:$G$55)*Assumptions!$B$22 -> 0 | V14: =SUMIF(Assumptions!$F$54:$F$55,21,Assumptions!$G$54:$G$55)*Assumptions!$B$22 -> 0 | W14: =SUMIF(Assumptions!$F$54:$F$55,22,Assumptions!$G$54:$G$55)*Assumptions!$B$22 -> 0 | X14: =SUMIF(Assumptions!$F$54:$F$55,23,Assumptions!$G$54:$G$55)*Assumptions!$B$22 -> 0 | Y14: =SUMIF(Assumptions!$F$54:$F$55,24,Assumptions!$G$54:$G$55)*Assumptions!$B$22 -> 0 | Z14: =SUM(B14:Y14) -> 60000
A15: 当月设备折旧 | B15: =SUMPRODUCT((1-Assumptions!$F$54:$F$55+1>0)*(1-Assumptions!$F$54:$F$55+1<=Assumptions!$B$11)*Assumptions!$G$54:$G$55)*Assumptions!$B$22/Assumptions!$B$11 -> 1041.6667 | C15: =SUMPRODUCT((2-Assumptions!$F$54:$F$55+1>0)*(2-Assumptions!$F$54:$F$55+1<=Assumptions!$B$11)*Assumptions!$G$54:$G$55)*Assumptions!$B$22/Assumptions!$B$11 -> 1041.6667 | D15: =SUMPRODUCT((3-Assumptions!$F$54:$F$55+1>0)*(3-Assumptions!$F$54:$F$55+1<=Assumptions!$B$11)*Assumptions!$G$54:$G$55)*Assumptions!$B$22/Assumptions!$B$11 -> 1041.6667 | E15: =SUMPRODUCT((4-Assumptions!$F$54:$F$55+1>0)*(4-Assumptions!$F$54:$F$55+1<=Assumptions!$B$11)*Assumptions!$G$54:$G$55)*Assumptions!$B$22/Assumptions!$B$11 -> 1041.6667 | F15: =SUMPRODUCT((5-Assumptions!$F$54:$F$55+1>0)*(5-Assumptions!$F$54:$F$55+1<=Assumptions!$B$11)*Assumptions!$G$54:$G$55)*Assumptions!$B$22/Assumptions!$B$11 -> 1041.6667 | G15: =SUMPRODUCT((6-Assumptions!$F$54:$F$55+1>0)*(6-Assumptions!$F$54:$F$55+1<=Assumptions!$B$11)*Assumptions!$G$54:$G$55)*Assumptions!$B$22/Assumptions!$B$11 -> 1041.6667 | H15: =SUMPRODUCT((7-Assumptions!$F$54:$F$55+1>0)*(7-Assumptions!$F$54:$F$55+1<=Assumptions!$B$11)*Assumptions!$G$54:$G$55)*Assumptions!$B$22/Assumptions!$B$11 -> 1666.6667 | I15: =SUMPRODUCT((8-Assumptions!$F$54:$F$55+1>0)*(8-Assumptions!$F$54:$F$55+1<=Assumptions!$B$11)*Assumptions!$G$54:$G$55)*Assumptions!$B$22/Assumptions!$B$11 -> 1666.6667 | J15: =SUMPRODUCT((9-Assumptions!$F$54:$F$55+1>0)*(9-Assumptions!$F$54:$F$55+1<=Assumptions!$B$11)*Assumptions!$G$54:$G$55)*Assumptions!$B$22/Assumptions!$B$11 -> 1666.6667 | K15: =SUMPRODUCT((10-Assumptions!$F$54:$F$55+1>0)*(10-Assumptions!$F$54:$F$55+1<=Assumptions!$B$11)*Assumptions!$G$54:$G$55)*Assumptions!$B$22/Assumptions!$B$11 -> 1666.6667 | L15: =SUMPRODUCT((11-Assumptions!$F$54:$F$55+1>0)*(11-Assumptions!$F$54:$F$55+1<=Assumptions!$B$11)*Assumptions!$G$54:$G$55)*Assumptions!$B$22/Assumptions!$B$11 -> 1666.6667 | M15: =SUMPRODUCT((12-Assumptions!$F$54:$F$55+1>0)*(12-Assumptions!$F$54:$F$55+1<=Assumptions!$B$11)*Assumptions!$G$54:$G$55)*Assumptions!$B$22/Assumptions!$B$11 -> 1666.6667 | N15: =SUMPRODUCT((13-Assumptions!$F$54:$F$55+1>0)*(13-Assumptions!$F$54:$F$55+1<=Assumptions!$B$11)*Assumptions!$G$54:$G$55)*Assumptions!$B$22/Assumptions!$B$11 -> 1666.6667 | O15: =SUMPRODUCT((14-Assumptions!$F$54:$F$55+1>0)*(14-Assumptions!$F$54:$F$55+1<=Assumptions!$B$11)*Assumptions!$G$54:$G$55)*Assumptions!$B$22/Assumptions!$B$11 -> 1666.6667 | P15: =SUMPRODUCT((15-Assumptions!$F$54:$F$55+1>0)*(15-Assumptions!$F$54:$F$55+1<=Assumptions!$B$11)*Assumptions!$G$54:$G$55)*Assumptions!$B$22/Assumptions!$B$11 -> 1666.6667 | Q15: =SUMPRODUCT((16-Assumptions!$F$54:$F$55+1>0)*(16-Assumptions!$F$54:$F$55+1<=Assumptions!$B$11)*Assumptions!$G$54:$G$55)*Assumptions!$B$22/Assumptions!$B$11 -> 1666.6667 | R15: =SUMPRODUCT((17-Assumptions!$F$54:$F$55+1>0)*(17-Assumptions!$F$54:$F$55+1<=Assumptions!$B$11)*Assumptions!$G$54:$G$55)*Assumptions!$B$22/Assumptions!$B$11 -> 1666.6667 | S15: =SUMPRODUCT((18-Assumptions!$F$54:$F$55+1>0)*(18-Assumptions!$F$54:$F$55+1<=Assumptions!$B$11)*Assumptions!$G$54:$G$55)*Assumptions!$B$22/Assumptions!$B$11 -> 1666.6667 | T15: =SUMPRODUCT((19-Assumptions!$F$54:$F$55+1>0)*(19-Assumptions!$F$54:$F$55+1<=Assumptions!$B$11)*Assumptions!$G$54:$G$55)*Assumptions!$B$22/Assumptions!$B$11 -> 1666.6667 | U15: =SUMPRODUCT((20-Assumptions!$F$54:$F$55+1>0)*(20-Assumptions!$F$54:$F$55+1<=Assumptions!$B$11)*Assumptions!$G$54:$G$55)*Assumptions!$B$22/Assumptions!$B$11 -> 1666.6667 | V15: =SUMPRODUCT((21-Assumptions!$F$54:$F$55+1>0)*(21-Assumptions!$F$54:$F$55+1<=Assumptions!$B$11)*Assumptions!$G$54:$G$55)*Assumptions!$B$22/Assumptions!$B$11 -> 1666.6667 | W15: =SUMPRODUCT((22-Assumptions!$F$54:$F$55+1>0)*(22-Assumptions!$F$54:$F$55+1<=Assumptions!$B$11)*Assumptions!$G$54:$G$55)*Assumptions!$B$22/Assumptions!$B$11 -> 1666.6667 | X15: =SUMPRODUCT((23-Assumptions!$F$54:$F$55+1>0)*(23-Assumptions!$F$54:$F$55+1<=Assumptions!$B$11)*Assumptions!$G$54:$G$55)*Assumptions!$B$22/Assumptions!$B$11 -> 1666.6667 | Y15: =SUMPRODUCT((24-Assumptions!$F$54:$F$55+1>0)*(24-Assumptions!$F$54:$F$55+1<=Assumptions!$B$11)*Assumptions!$G$54:$G$55)*Assumptions!$B$22/Assumptions!$B$11 -> 1666.6667 | Z15: =SUM(B15:Y15) -> 36250
A16: 损益费用合计 | B16: =B13+B15 -> 40431.025 | C16: =C13+C15 -> 40431.025 | D16: =D13+D15 -> 40431.025 | E16: =E13+E15 -> 47181.025 | F16: =F13+F15 -> 47181.025 | G16: =G13+G15 -> 69681.025 | H16: =H13+H15 -> 67500.704 | I16: =I13+I15 -> 67500.704 | ... Y16: =Y13+Y15 -> 306528.91 | Z16: =SUM(B16:Y16) -> 2576158.6
A17: 常规固定与专项支出 | B17: =SUM(B4:B10) -> 39389.358 | C17: =SUM(C4:C10) -> 39389.358 | D17: =SUM(D4:D10) -> 39389.358 | E17: =SUM(E4:E10) -> 46139.358 | F17: =SUM(F4:F10) -> 46139.358 | G17: =SUM(G4:G10) -> 68639.358 | H17: =SUM(H4:H10) -> 65834.037 | I17: =SUM(I4:I10) -> 65834.037 | ... Y17: =SUM(Y4:Y10) -> 101834.04 | Z17: =SUM(B17:Y17) -> 1626098.8
A18: 常规经常性支出 | B18: =SUM(B4:B9) -> 39389.358 | C18: =SUM(C4:C9) -> 39389.358 | D18: =SUM(D4:D9) -> 39389.358 | E18: =SUM(E4:E9) -> 46139.358 | F18: =SUM(F4:F9) -> 46139.358 | G18: =SUM(G4:G9) -> 46139.358 | H18: =SUM(H4:H9) -> 65834.037 | I18: =SUM(I4:I9) -> 65834.037 | ... Y18: =SUM(Y4:Y9) -> 71834.037 | Z18: =SUM(B18:Y18) -> 1513598.8
A26: 基准建设
A27: 月份 | B27: =EDATE(Assumptions!$B$3,0) -> 46327 | C27: =EDATE(Assumptions!$B$3,1) -> 46357 | D27: =EDATE(Assumptions!$B$3,2) -> 46388 | E27: =EDATE(Assumptions!$B$3,3) -> 46419 | F27: =EDATE(Assumptions!$B$3,4) -> 46447 | G27: =EDATE(Assumptions!$B$3,5) -> 46478 | H27: =EDATE(Assumptions!$B$3,6) -> 46508 | I27: =EDATE(Assumptions!$B$3,7) -> 46539 | J27: =EDATE(Assumptions!$B$3,8) -> 46569 | K27: =EDATE(Assumptions!$B$3,9) -> 46600 | L27: =EDATE(Assumptions!$B$3,10) -> 46631 | M27: =EDATE(Assumptions!$B$3,11) -> 46661 | N27: =EDATE(Assumptions!$B$3,12) -> 46692 | O27: =EDATE(Assumptions!$B$3,13) -> 46722 | P27: =EDATE(Assumptions!$B$3,14) -> 46753 | Q27: =EDATE(Assumptions!$B$3,15) -> 46784 | R27: =EDATE(Assumptions!$B$3,16) -> 46813 | S27: =EDATE(Assumptions!$B$3,17) -> 46844 | T27: =EDATE(Assumptions!$B$3,18) -> 46874 | U27: =EDATE(Assumptions!$B$3,19) -> 46905 | V27: =EDATE(Assumptions!$B$3,20) -> 46935 | W27: =EDATE(Assumptions!$B$3,21) -> 46966 | X27: =EDATE(Assumptions!$B$3,22) -> 46997 | Y27: =EDATE(Assumptions!$B$3,23) -> 47027 | Z27: 24个月合计 / 期末
A28: 等效资源人力 | B28: =IF(1<=6,Assumptions!$C$17,Assumptions!$C$18) -> 3 | C28: =IF(2<=6,Assumptions!$C$17,Assumptions!$C$18) -> 3 | D28: =IF(3<=6,Assumptions!$C$17,Assumptions!$C$18) -> 3 | E28: =IF(4<=6,Assumptions!$C$17,Assumptions!$C$18) -> 3 | F28: =IF(5<=6,Assumptions!$C$17,Assumptions!$C$18) -> 3 | G28: =IF(6<=6,Assumptions!$C$17,Assumptions!$C$18) -> 3 | H28: =IF(7<=6,Assumptions!$C$17,Assumptions!$C$18) -> 4 | I28: =IF(8<=6,Assumptions!$C$17,Assumptions!$C$18) -> 4 | J28: =IF(9<=6,Assumptions!$C$17,Assumptions!$C$18) -> 4 | K28: =IF(10<=6,Assumptions!$C$17,Assumptions!$C$18) -> 4 | L28: =IF(11<=6,Assumptions!$C$17,Assumptions!$C$18) -> 4 | M28: =IF(12<=6,Assumptions!$C$17,Assumptions!$C$18) -> 4 | N28: =IF(13<=6,Assumptions!$C$17,Assumptions!$C$18) -> 4 | O28: =IF(14<=6,Assumptions!$C$17,Assumptions!$C$18) -> 4 | P28: =IF(15<=6,Assumptions!$C$17,Assumptions!$C$18) -> 4 | Q28: =IF(16<=6,Assumptions!$C$17,Assumptions!$C$18) -> 4 | R28: =IF(17<=6,Assumptions!$C$17,Assumptions!$C$18) -> 4 | S28: =IF(18<=6,Assumptions!$C$17,Assumptions!$C$18) -> 4 | T28: =IF(19<=6,Assumptions!$C$17,Assumptions!$C$18) -> 4 | U28: =IF(20<=6,Assumptions!$C$17,Assumptions!$C$18) -> 4 | V28: =IF(21<=6,Assumptions!$C$17,Assumptions!$C$18) -> 4 | W28: =IF(22<=6,Assumptions!$C$17,Assumptions!$C$18) -> 4 | X28: =IF(23<=6,Assumptions!$C$17,Assumptions!$C$18) -> 4 | Y28: =IF(24<=6,Assumptions!$C$17,Assumptions!$C$18) -> 4 | Z28: =SUM(B28:Y28) -> 90
A29: 综合人力现金 | B29: =B28*Assumptions!$C$19 -> 60000 | C29: =C28*Assumptions!$C$19 -> 60000 | D29: =D28*Assumptions!$C$19 -> 60000 | E29: =E28*Assumptions!$C$19 -> 60000 | F29: =F28*Assumptions!$C$19 -> 60000 | G29: =G28*Assumptions!$C$19 -> 60000 | H29: =H28*Assumptions!$C$19 -> 80000 | I29: =I28*Assumptions!$C$19 -> 80000 | ... Y29: =Y28*Assumptions!$C$19 -> 80000 | Z29: =SUM(B29:Y29) -> 1800000
A30: 内部研发Agent预算 | B30: =B28*Assumptions!$B$32*Assumptions!$C$22 -> 5778.7158 | C30: =C28*Assumptions!$B$32*Assumptions!$C$22 -> 5778.7158 | D30: =D28*Assumptions!$B$32*Assumptions!$C$22 -> 5778.7158 | E30: =E28*Assumptions!$B$32*Assumptions!$C$22 -> 5778.7158 | F30: =F28*Assumptions!$B$32*Assumptions!$C$22 -> 5778.7158 | G30: =G28*Assumptions!$B$32*Assumptions!$C$22 -> 5778.7158 | H30: =H28*Assumptions!$B$32*Assumptions!$C$22 -> 7704.9544 | I30: =I28*Assumptions!$B$32*Assumptions!$C$22 -> 7704.9544 | ... Y30: =Y28*Assumptions!$B$32*Assumptions!$C$22 -> 7704.9544 | Z30: =SUM(B30:Y30) -> 173361.47
