Workbook

Sheet Summary
C2: Blocky Studio | 财务汇总
C3: 人民币 · 2027–2029示例测算
C6: 年度情景 | D6: 基准 2027 | E6: 基准 2028 | F6: 基准 2029 | G6: 悲观 2027 | H6: 悲观 2028 | I6: 悲观 2029 | J6: 积极 2027 | K6: 积极 2028 | L6: 积极 2029
C8: 机构服务收入 | D8: ='Income Statement'!D8 -> 72000 | E8: ='Income Statement'!E8 -> 180000 | F8: ='Income Statement'!F8 -> 324000 | G8: ='Income Statement'!G8 -> 30000 | H8: ='Income Statement'!H8 -> 60000 | I8: ='Income Statement'!I8 -> 90000 | J8: ='Income Statement'!J8 -> 132000 | K8: ='Income Statement'!K8 -> 308000 | L8: ='Income Statement'!L8 -> 528000
C9: 总费用（含折旧/税费预算） | D9: ='Income Statement'!D15 -> 132640 | E9: ='Income Statement'!E15 -> 188400 | F9: ='Income Statement'!F15 -> 269680 | G9: ='Income Statement'!G15 -> 125200 | H9: ='Income Statement'!H15 -> 152800 | I9: ='Income Statement'!I15 -> 180400 | J9: ='Income Statement'!J15 -> 180940 | K9: ='Income Statement'!K15 -> 254860 | L9: ='Income Statement'!L15 -> 351760
C10: 经营损益 | D10: ='Income Statement'!D16 -> -60640 | E10: ='Income Statement'!E16 -> -8400 | F10: ='Income Statement'!F16 -> 54320 | G10: ='Income Statement'!G16 -> -95200 | H10: ='Income Statement'!H16 -> -92800 | I10: ='Income Statement'!I16 -> -90400 | J10: ='Income Statement'!J16 -> -48940 | K10: ='Income Statement'!K16 -> 53140 | L10: ='Income Statement'!L16 -> 176240
C11: 期末现金（未覆盖缺口） | D11: ='Cash Flow'!O12 -> -48640 | E11: ='Cash Flow'!AA12 -> -62040 | F11: ='Cash Flow'!AM12 -> -3720 | G11: ='Cash Flow'!O36 -> -83200 | H11: ='Cash Flow'!AA36 -> -172000 | I11: ='Cash Flow'!AM36 -> -258400 | J11: ='Cash Flow'!O60 -> -36940 | K11: ='Cash Flow'!AA60 -> 9200 | L11: ='Cash Flow'!AM60 -> 178440
C12: 期末现金（假设缺口已覆盖） | D12: ='Cash Flow'!O14 -> 54360 | E12: ='Cash Flow'!AA14 -> 40960 | F12: ='Cash Flow'!AM14 -> 99280 | G12: ='Cash Flow'!O38 -> 197900 | H12: ='Cash Flow'!AA38 -> 109100 | I12: ='Cash Flow'!AM38 -> 22700 | J12: ='Cash Flow'!O62 -> 38490 | K12: ='Cash Flow'!AA62 -> 84630 | L12: ='Cash Flow'!AM62 -> 253870
C13: 交付合同数 | D13: =SUM(Revenue!D8:O8) -> 4 | E13: =SUM(Revenue!P8:AA8) -> 10 | F13: =SUM(Revenue!AB8:AM8) -> 18 | G13: =SUM(Revenue!D26:O26) -> 2 | H13: =SUM(Revenue!P26:AA26) -> 4 | I13: =SUM(Revenue!AB26:AM26) -> 6 | J13: =SUM(Revenue!D44:O44) -> 6 | K13: =SUM(Revenue!P44:AA44) -> 14 | L13: =SUM(Revenue!AB44:AM44) -> 24
C14: 交付总工时 | D14: =SUM(Revenue!D12:O12) -> 320 | E14: =SUM(Revenue!P12:AA12) -> 800 | F14: =SUM(Revenue!AB12:AM12) -> 1440 | G14: =SUM(Revenue!D30:O30) -> 200 | H14: =SUM(Revenue!P30:AA30) -> 400 | I14: =SUM(Revenue!AB30:AM30) -> 600 | J14: =SUM(Revenue!D48:O48) -> 420 | K14: =SUM(Revenue!P48:AA48) -> 980 | L14: =SUM(Revenue!AB48:AM48) -> 1680
C15: 外部增援工时 | D15: =SUM(Revenue!D14:O14) -> 0 | E15: =SUM(Revenue!P14:AA14) -> 160 | F15: =SUM(Revenue!AB14:AM14) -> 720 | G15: =SUM(Revenue!D32:O32) -> 40 | H15: =SUM(Revenue!P32:AA32) -> 80 | I15: =SUM(Revenue!AB32:AM32) -> 120 | J15: =SUM(Revenue!D50:O50) -> 0 | K15: =SUM(Revenue!P50:AA50) -> 300 | L15: =SUM(Revenue!AB50:AM50) -> 900
C16: 直接成本 | D16: ='Income Statement'!D9 -> 33600 | E16: ='Income Statement'!E9 -> 87200 | F16: ='Income Statement'!F9 -> 165600 | G16: ='Income Statement'!G9 -> 26700 | H16: ='Income Statement'!H9 -> 53400 | I16: ='Income Statement'!I9 -> 80100 | J16: ='Income Statement'!J9 -> 48300 | K16: ='Income Statement'!K9 -> 118700 | L16: ='Income Statement'!L9 -> 211200
C17: 服务贡献（收入减直接成本） | D17: ='Income Statement'!D10 -> 38400 | E17: ='Income Statement'!E10 -> 92800 | F17: ='Income Statement'!F10 -> 158400 | G17: ='Income Statement'!G10 -> 3300 | H17: ='Income Statement'!H10 -> 6600 | I17: ='Income Statement'!I10 -> 9900 | J17: ='Income Statement'!J10 -> 83700 | K17: ='Income Statement'!K10 -> 189300 | L17: ='Income Statement'!L10 -> 316800
C18: 税费预算预留 | D18: ='Income Statement'!D13 -> 1440 | E18: ='Income Statement'!E13 -> 3600 | F18: ='Income Statement'!F13 -> 6480 | G18: ='Income Statement'!G13 -> 900 | H18: ='Income Statement'!H13 -> 1800 | I18: ='Income Statement'!I13 -> 2700 | J18: ='Income Statement'!J13 -> 2640 | K18: ='Income Statement'!K13 -> 6160 | L18: ='Income Statement'!L13 -> 10560
C20: 机构收入是服务合同交付测算；完整软件免费。未记录真实客户、试点或商业收入。
C21: 现金负数表示未覆盖资金缺口，不能作为真实银行余额；填补缺口的资金来源尚未承诺。
C22: 税费是收入比例预算预留，非税法计算；法定主体、纳税资格及实际税费仍待确认。
C23: 输入蓝色；同表公式黑色；跨表公式绿色。Assumptions与Revenue月度分布可调整。

Sheet Assumptions
C2: Blocky Studio | 规划假设
C3: 人民币 · 2027–2029示例测算
C8: 假设ID / 输入 | D8: 说明 | E8: 基准 | F8: 悲观 | G8: 积极 | H8: 单位 | I8: 口径与待确认事项
C10: A01 | D10: 2027合同数 | E10: 4 | F10: 2 | G10: 6 | H10: 份 | I10: 单次范围明确的课程试点/培训/配置支持服务；未签合同
C11: A02 | D11: 2028合同数 | E11: 10 | F11: 4 | G11: 14 | H11: 份 | I11: 不自动假设续约；全部为当年交付合同
C12: A03 | D12: 2029合同数 | E12: 18 | F12: 6 | G12: 24 | H12: 份 | I12: 可触达客户名单与转化均待验证
C13: A04 | D13: 每合同含税总预算 | E13: 18000 | F13: 15000 | G13: 22000 | H13: 元/份 | I13: 示例均价；具体机构须逐项报价
C14: A05 | D14: 每合同交付工时 | E14: 80 | F14: 100 | G14: 70 | H14: 小时/份 | I14: 备课、培训、安装配置、支持；不含固定核心工作
C15: A06 | D15: 交付内部工时预算 | E15: 80 | F15: 90 | G15: 80 | H15: 元/小时 | I15: 交付专项报酬；不与固定核心工作工时重叠
C16: A07 | D16: 外部增援工时预算 | E16: 100 | F16: 110 | G16: 100 | H16: 元/小时 | I16: 超出学生团队交付工时的外包预算；尚未聘用
C17: A08 | D17: 每合同输入Token | E17: 80 | F17: 120 | G17: 100 | H17: 百万Token | I17: 额度上限规划；没有整班实测
C18: A09 | D18: 每合同输出Token | E18: 20 | F18: 30 | G18: 25 | H18: 百万Token | I18: 包含重试的预算假设，非实测消费
C19: A10 | D19: 输入Token预算单价 | E19: 10 | F19: 15 | G19: 10 | H19: 元/百万Token | I19: 保守预算假设，非供应商报价；需按实际模型替换
C20: A11 | D20: 输出Token预算单价 | E20: 30 | F20: 45 | G20: 30 | H20: 元/百万Token | I20: 预算假设；客户自带API时另行报价
C21: A12 | D21: 每合同其他直接成本 | E21: 600 | F21: 800 | G21: 700 | H21: 元/份 | I21: 交通、资料及现场配置耗材预算
... C32: A23 | D32: 每月外部增援上限 | E32: 160 | F32: 160 | G32: 160 | H32: 小时/月 | I32: 按项目招募预算，未聘用；超出则拒绝接单/改期
C35: 所有蓝色数值为可调规划假设；无历史收入、试点、客户或真实资金凭证。
C36: 工时隔离：固定核心160小时/月；交付可用80小时/月；超出部分按外部增援工时预算计费。
C37: 软件完整免费；机构收入仅来自范围明确的服务与模型预算；班级管理和计费平台未作为现售能力。

Sheet Revenue
C2: Blocky | 机构服务收入
C3: 人民币 · 2027–2029示例测算
C6: 基准 | D6: 46388 | E6: 46419 | F6: 46447 | G6: 46478 | H6: 46508 | I6: 46539 | J6: 46569 | K6: 46600 | L6: 46631 | M6: 46661 | N6: 46692 | O6: 46722 | P6: 46753 | Q6: 46784 | R6: 46813 | S6: 46844 | T6: 46874 | U6: 46905 | V6: 46935 | W6: 46966 | X6: 46997 | Y6: 47027 | Z6: 47058 | AA6: 47088 | AB6: 47119 | AC6: 47150 | AD6: 47178 | AE6: 47209 | AF6: 47239 | AG6: 47270 | AH6: 47300 | AI6: 47331 | AJ6: 47362 | AK6: 47392 | AL6: 47423 | AM6: 47453
C7: 月度分布权重（可调） | D7: 0 | E7: 0 | F7: 0 | G7: 1 | H7: 0 | I7: 1 | J7: 0 | K7: 0 | L7: 1 | M7: 1 | N7: 0 | O7: 0 | P7: 0 | Q7: 0 | R7: 1 | S7: 1 | T7: 1 | U7: 1 | V7: 0 | W7: 0 | X7: 2 | Y7: 2 | Z7: 1 | AA7: 1 | AB7: 0 | AC7: 1 | AD7: 2 | AE7: 2 | AF7: 2 | AG7: 2 | AH7: 0 | AI7: 0 | AJ7: 3 | AK7: 3 | AL7: 2 | AM7: 1
C8: 合同交付数量 | D8: =IF(SUM(D7:O7)=0,0,D7/SUM(D7:O7)*Assumptions!$E$10) -> 0 | E8: =IF(SUM(D7:O7)=0,0,E7/SUM(D7:O7)*Assumptions!$E$10) -> 0 | F8: =IF(SUM(D7:O7)=0,0,F7/SUM(D7:O7)*Assumptions!$E$10) -> 0 | G8: =IF(SUM(D7:O7)=0,0,G7/SUM(D7:O7)*Assumptions!$E$10) -> 1 | H8: =IF(SUM(D7:O7)=0,0,H7/SUM(D7:O7)*Assumptions!$E$10) -> 0 | I8: =IF(SUM(D7:O7)=0,0,I7/SUM(D7:O7)*Assumptions!$E$10) -> 1 | J8: =IF(SUM(D7:O7)=0,0,J7/SUM(D7:O7)*Assumptions!$E$10) -> 0 | K8: =IF(SUM(D7:O7)=0,0,K7/SUM(D7:O7)*Assumptions!$E$10) -> 0 | L8: =IF(SUM(D7:O7)=0,0,L7/SUM(D7:O7)*Assumptions!$E$10) -> 1 | M8: =IF(SUM(D7:O7)=0,0,M7/SUM(D7:O7)*Assumptions!$E$10) -> 1 | N8: =IF(SUM(D7:O7)=0,0,N7/SUM(D7:O7)*Assumptions!$E$10) -> 0 | O8: =IF(SUM(D7:O7)=0,0,O7/SUM(D7:O7)*Assumptions!$E$10) -> 0 | P8: =IF(SUM(P7:AA7)=0,0,P7/SUM(P7:AA7)*Assumptions!$E$11) -> 0 | Q8: =IF(SUM(P7:AA7)=0,0,Q7/SUM(P7:AA7)*Assumptions!$E$11) -> 0 | R8: =IF(SUM(P7:AA7)=0,0,R7/SUM(P7:AA7)*Assumptions!$E$11) -> 1 | S8: =IF(SUM(P7:AA7)=0,0,S7/SUM(P7:AA7)*Assumptions!$E$11) -> 1 | T8: =IF(SUM(P7:AA7)=0,0,T7/SUM(P7:AA7)*Assumptions!$E$11) -> 1 | U8: =IF(SUM(P7:AA7)=0,0,U7/SUM(P7:AA7)*Assumptions!$E$11) -> 1 | V8: =IF(SUM(P7:AA7)=0,0,V7/SUM(P7:AA7)*Assumptions!$E$11) -> 0 | W8: =IF(SUM(P7:AA7)=0,0,W7/SUM(P7:AA7)*Assumptions!$E$11) -> 0 | X8: =IF(SUM(P7:AA7)=0,0,X7/SUM(P7:AA7)*Assumptions!$E$11) -> 2 | Y8: =IF(SUM(P7:AA7)=0,0,Y7/SUM(P7:AA7)*Assumptions!$E$11) -> 2 | Z8: =IF(SUM(P7:AA7)=0,0,Z7/SUM(P7:AA7)*Assumptions!$E$11) -> 1 | AA8: =IF(SUM(P7:AA7)=0,0,AA7/SUM(P7:AA7)*Assumptions!$E$11) -> 1 | AB8: =IF(SUM(AB7:AM7)=0,0,AB7/SUM(AB7:AM7)*Assumptions!$E$12) -> 0 | AC8: =IF(SUM(AB7:AM7)=0,0,AC7/SUM(AB7:AM7)*Assumptions!$E$12) -> 1 | AD8: =IF(SUM(AB7:AM7)=0,0,AD7/SUM(AB7:AM7)*Assumptions!$E$12) -> 2 | AE8: =IF(SUM(AB7:AM7)=0,0,AE7/SUM(AB7:AM7)*Assumptions!$E$12) -> 2 | AF8: =IF(SUM(AB7:AM7)=0,0,AF7/SUM(AB7:AM7)*Assumptions!$E$12) -> 2 | AG8: =IF(SUM(AB7:AM7)=0,0,AG7/SUM(AB7:AM7)*Assumptions!$E$12) -> 2 | AH8: =IF(SUM(AB7:AM7)=0,0,AH7/SUM(AB7:AM7)*Assumptions!$E$12) -> 0 | AI8: =IF(SUM(AB7:AM7)=0,0,AI7/SUM(AB7:AM7)*Assumptions!$E$12) -> 0 | AJ8: =IF(SUM(AB7:AM7)=0,0,AJ7/SUM(AB7:AM7)*Assumptions!$E$12) -> 3 | AK8: =IF(SUM(AB7:AM7)=0,0,AK7/SUM(AB7:AM7)*Assumptions!$E$12) -> 3 | AL8: =IF(SUM(AB7:AM7)=0,0,AL7/SUM(AB7:AM7)*Assumptions!$E$12) -> 2 | AM8: =IF(SUM(AB7:AM7)=0,0,AM7/SUM(AB7:AM7)*Assumptions!$E$12) -> 1
C9: 机构服务收入 | D9: =D8*Assumptions!$E$13 -> 0 | E9: =E8*Assumptions!$E$13 -> 0 | F9: =F8*Assumptions!$E$13 -> 0 | G9: =G8*Assumptions!$E$13 -> 18000 | H9: =H8*Assumptions!$E$13 -> 0 | I9: =I8*Assumptions!$E$13 -> 18000 | J9: =J8*Assumptions!$E$13 -> 0 | K9: =K8*Assumptions!$E$13 -> 0 | ... AM9: =AM8*Assumptions!$E$13 -> 18000
C10: 当月收款 | D10: =D9*Assumptions!$E$28 -> 0 | E10: =E9*Assumptions!$E$28+D11 -> 0 | F10: =F9*Assumptions!$E$28+E11 -> 0 | G10: =G9*Assumptions!$E$28+F11 -> 9000 | H10: =H9*Assumptions!$E$28+G11 -> 9000 | I10: =I9*Assumptions!$E$28+H11 -> 9000 | J10: =J9*Assumptions!$E$28+I11 -> 9000 | K10: =K9*Assumptions!$E$28+J11 -> 0 | L10: =L9*Assumptions!$E$28+K11 -> 9000 | ... AM10: =AM9*Assumptions!$E$28+AL11 -> 27000
C11: 期末应收 | D11: =D9*(1-Assumptions!$E$28) -> 0 | E11: =E9*(1-Assumptions!$E$28) -> 0 | F11: =F9*(1-Assumptions!$E$28) -> 0 | G11: =G9*(1-Assumptions!$E$28) -> 9000 | H11: =H9*(1-Assumptions!$E$28) -> 0 | I11: =I9*(1-Assumptions!$E$28) -> 9000 | J11: =J9*(1-Assumptions!$E$28) -> 0 | K11: =K9*(1-Assumptions!$E$28) -> 0 | ... AM11: =AM9*(1-Assumptions!$E$28) -> 9000
C12: 交付工时 | D12: =D8*Assumptions!$E$14 -> 0 | E12: =E8*Assumptions!$E$14 -> 0 | F12: =F8*Assumptions!$E$14 -> 0 | G12: =G8*Assumptions!$E$14 -> 80 | H12: =H8*Assumptions!$E$14 -> 0 | I12: =I8*Assumptions!$E$14 -> 80 | J12: =J8*Assumptions!$E$14 -> 0 | K12: =K8*Assumptions!$E$14 -> 0 | ... AM12: =AM8*Assumptions!$E$14 -> 80
C13: 内部交付工时 | D13: =MIN(D12,MAX(0,Assumptions!$E$30-Assumptions!$E$31)) -> 0 | E13: =MIN(E12,MAX(0,Assumptions!$E$30-Assumptions!$E$31)) -> 0 | F13: =MIN(F12,MAX(0,Assumptions!$E$30-Assumptions!$E$31)) -> 0 | G13: =MIN(G12,MAX(0,Assumptions!$E$30-Assumptions!$E$31)) -> 80 | H13: =MIN(H12,MAX(0,Assumptions!$E$30-Assumptions!$E$31)) -> 0 | I13: =MIN(I12,MAX(0,Assumptions!$E$30-Assumptions!$E$31)) -> 80 | J13: =MIN(J12,MAX(0,Assumptions!$E$30-Assumptions!$E$31)) -> 0 | K13: =MIN(K12,MAX(0,Assumptions!$E$30-Assumptions!$E$31)) -> 0 | ... AM13: =MIN(AM12,MAX(0,Assumptions!$E$30-Assumptions!$E$31)) -> 80
C14: 外部增援工时 | D14: =MAX(0,D12-D13) -> 0 | E14: =MAX(0,E12-E13) -> 0 | F14: =MAX(0,F12-F13) -> 0 | G14: =MAX(0,G12-G13) -> 0 | H14: =MAX(0,H12-H13) -> 0 | I14: =MAX(0,I12-I13) -> 0 | J14: =MAX(0,J12-J13) -> 0 | K14: =MAX(0,K12-K13) -> 0 | ... AM14: =MAX(0,AM12-AM13) -> 0
C15: 交付能力余量 | D15: =MAX(0,Assumptions!$E$30-Assumptions!$E$31)+Assumptions!$E$32-D12 -> 240 | E15: =MAX(0,Assumptions!$E$30-Assumptions!$E$31)+Assumptions!$E$32-E12 -> 240 | F15: =MAX(0,Assumptions!$E$30-Assumptions!$E$31)+Assumptions!$E$32-F12 -> 240 | G15: =MAX(0,Assumptions!$E$30-Assumptions!$E$31)+Assumptions!$E$32-G12 -> 160 | H15: =MAX(0,Assumptions!$E$30-Assumptions!$E$31)+Assumptions!$E$32-H12 -> 240 | I15: =MAX(0,Assumptions!$E$30-Assumptions!$E$31)+Assumptions!$E$32-I12 -> 160 | J15: =MAX(0,Assumptions!$E$30-Assumptions!$E$31)+Assumptions!$E$32-J12 -> 240 | K15: =MAX(0,Assumptions!$E$30-Assumptions!$E$31)+Assumptions!$E$32-K12 -> 240 | ... AM15: =MAX(0,Assumptions!$E$30-Assumptions!$E$31)+Assumptions!$E$32-AM12 -> 160
C16: 合同分配整数差额 | D16: =ABS(D8-ROUND(D8,0)) -> 0 | E16: =ABS(E8-ROUND(E8,0)) -> 0 | F16: =ABS(F8-ROUND(F8,0)) -> 0 | G16: =ABS(G8-ROUND(G8,0)) -> 0 | H16: =ABS(H8-ROUND(H8,0)) -> 0 | I16: =ABS(I8-ROUND(I8,0)) -> 0 | J16: =ABS(J8-ROUND(J8,0)) -> 0 | K16: =ABS(K8-ROUND(K8,0)) -> 0 | ... AM16: =ABS(AM8-ROUND(AM8,0)) -> 0
C24: 悲观 | D24: 46388 | E24: 46419 | F24: 46447 | G24: 46478 | H24: 46508 | I24: 46539 | J24: 46569 | K24: 46600 | L24: 46631 | M24: 46661 | N24: 46692 | O24: 46722 | P24: 46753 | Q24: 46784 | R24: 46813 | S24: 46844 | T24: 46874 | U24: 46905 | V24: 46935 | W24: 46966 | X24: 46997 | Y24: 47027 | Z24: 47058 | AA24: 47088 | AB24: 47119 | AC24: 47150 | AD24: 47178 | AE24: 47209 | AF24: 47239 | AG24: 47270 | AH24: 47300 | AI24: 47331 | AJ24: 47362 | AK24: 47392 | AL24: 47423 | AM24: 47453
C25: 月度分布权重（可调） | D25: 0 | E25: 0 | F25: 0 | G25: 0 | H25: 1 | I25: 0 | J25: 0 | K25: 0 | L25: 0 | M25: 1 | N25: 0 | O25: 0 | P25: 0 | Q25: 0 | R25: 0 | S25: 1 | T25: 0 | U25: 1 | V25: 0 | W25: 0 | X25: 1 | Y25: 1 | Z25: 0 | AA25: 0 | AB25: 0 | AC25: 0 | AD25: 1 | AE25: 0 | AF25: 1 | AG25: 1 | AH25: 0 | AI25: 0 | AJ25: 1 | AK25: 1 | AL25: 1 | AM25: 0
C26: 合同交付数量 | D26: =IF(SUM(D25:O25)=0,0,D25/SUM(D25:O25)*Assumptions!$F$10) -> 0 | E26: =IF(SUM(D25:O25)=0,0,E25/SUM(D25:O25)*Assumptions!$F$10) -> 0 | F26: =IF(SUM(D25:O25)=0,0,F25/SUM(D25:O25)*Assumptions!$F$10) -> 0 | G26: =IF(SUM(D25:O25)=0,0,G25/SUM(D25:O25)*Assumptions!$F$10) -> 0 | H26: =IF(SUM(D25:O25)=0,0,H25/SUM(D25:O25)*Assumptions!$F$10) -> 1 | I26: =IF(SUM(D25:O25)=0,0,I25/SUM(D25:O25)*Assumptions!$F$10) -> 0 | J26: =IF(SUM(D25:O25)=0,0,J25/SUM(D25:O25)*Assumptions!$F$10) -> 0 | K26: =IF(SUM(D25:O25)=0,0,K25/SUM(D25:O25)*Assumptions!$F$10) -> 0 | L26: =IF(SUM(D25:O25)=0,0,L25/SUM(D25:O25)*Assumptions!$F$10) -> 0 | M26: =IF(SUM(D25:O25)=0,0,M25/SUM(D25:O25)*Assumptions!$F$10) -> 1 | N26: =IF(SUM(D25:O25)=0,0,N25/SUM(D25:O25)*Assumptions!$F$10) -> 0 | O26: =IF(SUM(D25:O25)=0,0,O25/SUM(D25:O25)*Assumptions!$F$10) -> 0 | P26: =IF(SUM(P25:AA25)=0,0,P25/SUM(P25:AA25)*Assumptions!$F$11) -> 0 | Q26: =IF(SUM(P25:AA25)=0,0,Q25/SUM(P25:AA25)*Assumptions!$F$11) -> 0 | R26: =IF(SUM(P25:AA25)=0,0,R25/SUM(P25:AA25)*Assumptions!$F$11) -> 0 | S26: =IF(SUM(P25:AA25)=0,0,S25/SUM(P25:AA25)*Assumptions!$F$11) -> 1 | T26: =IF(SUM(P25:AA25)=0,0,T25/SUM(P25:AA25)*Assumptions!$F$11) -> 0 | U26: =IF(SUM(P25:AA25)=0,0,U25/SUM(P25:AA25)*Assumptions!$F$11) -> 1 | V26: =IF(SUM(P25:AA25)=0,0,V25/SUM(P25:AA25)*Assumptions!$F$11) -> 0 | W26: =IF(SUM(P25:AA25)=0,0,W25/SUM(P25:AA25)*Assumptions!$F$11) -> 0 | X26: =IF(SUM(P25:AA25)=0,0,X25/SUM(P25:AA25)*Assumptions!$F$11) -> 1 | Y26: =IF(SUM(P25:AA25)=0,0,Y25/SUM(P25:AA25)*Assumptions!$F$11) -> 1 | Z26: =IF(SUM(P25:AA25)=0,0,Z25/SUM(P25:AA25)*Assumptions!$F$11) -> 0 | AA26: =IF(SUM(P25:AA25)=0,0,AA25/SUM(P25:AA25)*Assumptions!$F$11) -> 0 | AB26: =IF(SUM(AB25:AM25)=0,0,AB25/SUM(AB25:AM25)*Assumptions!$F$12) -> 0 | AC26: =IF(SUM(AB25:AM25)=0,0,AC25/SUM(AB25:AM25)*Assumptions!$F$12) -> 0 | AD26: =IF(SUM(AB25:AM25)=0,0,AD25/SUM(AB25:AM25)*Assumptions!$F$12) -> 1 | AE26: =IF(SUM(AB25:AM25)=0,0,AE25/SUM(AB25:AM25)*Assumptions!$F$12) -> 0 | AF26: =IF(SUM(AB25:AM25)=0,0,AF25/SUM(AB25:AM25)*Assumptions!$F$12) -> 1 | AG26: =IF(SUM(AB25:AM25)=0,0,AG25/SUM(AB25:AM25)*Assumptions!$F$12) -> 1 | AH26: =IF(SUM(AB25:AM25)=0,0,AH25/SUM(AB25:AM25)*Assumptions!$F$12) -> 0 | AI26: =IF(SUM(AB25:AM25)=0,0,AI25/SUM(AB25:AM25)*Assumptions!$F$12) -> 0 | AJ26: =IF(SUM(AB25:AM25)=0,0,AJ25/SUM(AB25:AM25)*Assumptions!$F$12) -> 1 | AK26: =IF(SUM(AB25:AM25)=0,0,AK25/SUM(AB25:AM25)*Assumptions!$F$12) -> 1 | AL26: =IF(SUM(AB25:AM25)=0,0,AL25/SUM(AB25:AM25)*Assumptions!$F$12) -> 1 | AM26: =IF(SUM(AB25:AM25)=0,0,AM25/SUM(AB25:AM25)*Assumptions!$F$12) -> 0
C27: 机构服务收入 | D27: =D26*Assumptions!$F$13 -> 0 | E27: =E26*Assumptions!$F$13 -> 0 | F27: =F26*Assumptions!$F$13 -> 0 | G27: =G26*Assumptions!$F$13 -> 0 | H27: =H26*Assumptions!$F$13 -> 15000 | I27: =I26*Assumptions!$F$13 -> 0 | J27: =J26*Assumptions!$F$13 -> 0 | K27: =K26*Assumptions!$F$13 -> 0 | ... AM27: =AM26*Assumptions!$F$13 -> 0
C28: 当月收款 | D28: =D27*Assumptions!$F$28 -> 0 | E28: =E27*Assumptions!$F$28+D29 -> 0 | F28: =F27*Assumptions!$F$28+E29 -> 0 | G28: =G27*Assumptions!$F$28+F29 -> 0 | H28: =H27*Assumptions!$F$28+G29 -> 4500 | I28: =I27*Assumptions!$F$28+H29 -> 10500 | J28: =J27*Assumptions!$F$28+I29 -> 0 | K28: =K27*Assumptions!$F$28+J29 -> 0 | L28: =L27*Assumptions!$F$28+K29 -> 0 | ... AM28: =AM27*Assumptions!$F$28+AL29 -> 10500
C29: 期末应收 | D29: =D27*(1-Assumptions!$F$28) -> 0 | E29: =E27*(1-Assumptions!$F$28) -> 0 | F29: =F27*(1-Assumptions!$F$28) -> 0 | G29: =G27*(1-Assumptions!$F$28) -> 0 | H29: =H27*(1-Assumptions!$F$28) -> 10500 | I29: =I27*(1-Assumptions!$F$28) -> 0 | J29: =J27*(1-Assumptions!$F$28) -> 0 | K29: =K27*(1-Assumptions!$F$28) -> 0 | ... AM29: =AM27*(1-Assumptions!$F$28) -> 0
C30: 交付工时 | D30: =D26*Assumptions!$F$14 -> 0 | E30: =E26*Assumptions!$F$14 -> 0 | F30: =F26*Assumptions!$F$14 -> 0 | G30: =G26*Assumptions!$F$14 -> 0 | H30: =H26*Assumptions!$F$14 -> 100 | I30: =I26*Assumptions!$F$14 -> 0 | J30: =J26*Assumptions!$F$14 -> 0 | K30: =K26*Assumptions!$F$14 -> 0 | ... AM30: =AM26*Assumptions!$F$14 -> 0
C31: 内部交付工时 | D31: =MIN(D30,MAX(0,Assumptions!$F$30-Assumptions!$F$31)) -> 0 | E31: =MIN(E30,MAX(0,Assumptions!$F$30-Assumptions!$F$31)) -> 0 | F31: =MIN(F30,MAX(0,Assumptions!$F$30-Assumptions!$F$31)) -> 0 | G31: =MIN(G30,MAX(0,Assumptions!$F$30-Assumptions!$F$31)) -> 0 | H31: =MIN(H30,MAX(0,Assumptions!$F$30-Assumptions!$F$31)) -> 80 | I31: =MIN(I30,MAX(0,Assumptions!$F$30-Assumptions!$F$31)) -> 0 | J31: =MIN(J30,MAX(0,Assumptions!$F$30-Assumptions!$F$31)) -> 0 | K31: =MIN(K30,MAX(0,Assumptions!$F$30-Assumptions!$F$31)) -> 0 | ... AM31: =MIN(AM30,MAX(0,Assumptions!$F$30-Assumptions!$F$31)) -> 0
C32: 外部增援工时 | D32: =MAX(0,D30-D31) -> 0 | E32: =MAX(0,E30-E31) -> 0 | F32: =MAX(0,F30-F31) -> 0 | G32: =MAX(0,G30-G31) -> 0 | H32: =MAX(0,H30-H31) -> 20 | I32: =MAX(0,I30-I31) -> 0 | J32: =MAX(0,J30-J31) -> 0 | K32: =MAX(0,K30-K31) -> 0 | ... AM32: =MAX(0,AM30-AM31) -> 0
C33: 交付能力余量 | D33: =MAX(0,Assumptions!$F$30-Assumptions!$F$31)+Assumptions!$F$32-D30 -> 240 | E33: =MAX(0,Assumptions!$F$30-Assumptions!$F$31)+Assumptions!$F$32-E30 -> 240 | F33: =MAX(0,Assumptions!$F$30-Assumptions!$F$31)+Assumptions!$F$32-F30 -> 240 | G33: =MAX(0,Assumptions!$F$30-Assumptions!$F$31)+Assumptions!$F$32-G30 -> 240 | H33: =MAX(0,Assumptions!$F$30-Assumptions!$F$31)+Assumptions!$F$32-H30 -> 140 | I33: =MAX(0,Assumptions!$F$30-Assumptions!$F$31)+Assumptions!$F$32-I30 -> 240 | J33: =MAX(0,Assumptions!$F$30-Assumptions!$F$31)+Assumptions!$F$32-J30 -> 240 | K33: =MAX(0,Assumptions!$F$30-Assumptions!$F$31)+Assumptions!$F$32-K30 -> 240 | ... AM33: =MAX(0,Assumptions!$F$30-Assumptions!$F$31)+Assumptions!$F$32-AM30 -> 240
C34: 合同分配整数差额 | D34: =ABS(D26-ROUND(D26,0)) -> 0 | E34: =ABS(E26-ROUND(E26,0)) -> 0 | F34: =ABS(F26-ROUND(F26,0)) -> 0 | G34: =ABS(G26-ROUND(G26,0)) -> 0 | H34: =ABS(H26-ROUND(H26,0)) -> 0 | I34: =ABS(I26-ROUND(I26,0)) -> 0 | J34: =ABS(J26-ROUND(J26,0)) -> 0 | K34: =ABS(K26-ROUND(K26,0)) -> 0 | ... AM34: =ABS(AM26-ROUND(AM26,0)) -> 0
C42: 积极 | D42: 46388 | E42: 46419 | F42: 46447 | G42: 46478 | H42: 46508 | I42: 46539 | J42: 46569 | K42: 46600 | L42: 46631 | M42: 46661 | N42: 46692 | O42: 46722 | P42: 46753 | Q42: 46784 | R42: 46813 | S42: 46844 | T42: 46874 | U42: 46905 | V42: 46935 | W42: 46966 | X42: 46997 | Y42: 47027 | Z42: 47058 | AA42: 47088 | AB42: 47119 | AC42: 47150 | AD42: 47178 | AE42: 47209 | AF42: 47239 | AG42: 47270 | AH42: 47300 | AI42: 47331 | AJ42: 47362 | AK42: 47392 | AL42: 47423 | AM42: 47453
C43: 月度分布权重（可调） | D43: 0 | E43: 0 | F43: 1 | G43: 0 | H43: 1 | I43: 1 | J43: 0 | K43: 0 | L43: 1 | M43: 1 | N43: 1 | O43: 0 | P43: 0 | Q43: 1 | R43: 1 | S43: 2 | T43: 1 | U43: 2 | V43: 0 | W43: 0 | X43: 2 | Y43: 2 | Z43: 2 | AA43: 1 | AB43: 1 | AC43: 1 | AD43: 2 | AE43: 3 | AF43: 3 | AG43: 3 | AH43: 0 | AI43: 0 | AJ43: 3 | AK43: 3 | AL43: 3 | AM43: 2
C44: 合同交付数量 | D44: =IF(SUM(D43:O43)=0,0,D43/SUM(D43:O43)*Assumptions!$G$10) -> 0 | E44: =IF(SUM(D43:O43)=0,0,E43/SUM(D43:O43)*Assumptions!$G$10) -> 0 | F44: =IF(SUM(D43:O43)=0,0,F43/SUM(D43:O43)*Assumptions!$G$10) -> 1 | G44: =IF(SUM(D43:O43)=0,0,G43/SUM(D43:O43)*Assumptions!$G$10) -> 0 | H44: =IF(SUM(D43:O43)=0,0,H43/SUM(D43:O43)*Assumptions!$G$10) -> 1 | I44: =IF(SUM(D43:O43)=0,0,I43/SUM(D43:O43)*Assumptions!$G$10) -> 1 | J44: =IF(SUM(D43:O43)=0,0,J43/SUM(D43:O43)*Assumptions!$G$10) -> 0 | K44: =IF(SUM(D43:O43)=0,0,K43/SUM(D43:O43)*Assumptions!$G$10) -> 0 | L44: =IF(SUM(D43:O43)=0,0,L43/SUM(D43:O43)*Assumptions!$G$10) -> 1 | M44: =IF(SUM(D43:O43)=0,0,M43/SUM(D43:O43)*Assumptions!$G$10) -> 1 | N44: =IF(SUM(D43:O43)=0,0,N43/SUM(D43:O43)*Assumptions!$G$10) -> 1 | O44: =IF(SUM(D43:O43)=0,0,O43/SUM(D43:O43)*Assumptions!$G$10) -> 0 | P44: =IF(SUM(P43:AA43)=0,0,P43/SUM(P43:AA43)*Assumptions!$G$11) -> 0 | Q44: =IF(SUM(P43:AA43)=0,0,Q43/SUM(P43:AA43)*Assumptions!$G$11) -> 1 | R44: =IF(SUM(P43:AA43)=0,0,R43/SUM(P43:AA43)*Assumptions!$G$11) -> 1 | S44: =IF(SUM(P43:AA43)=0,0,S43/SUM(P43:AA43)*Assumptions!$G$11) -> 2 | T44: =IF(SUM(P43:AA43)=0,0,T43/SUM(P43:AA43)*Assumptions!$G$11) -> 1 | U44: =IF(SUM(P43:AA43)=0,0,U43/SUM(P43:AA43)*Assumptions!$G$11) -> 2 | V44: =IF(SUM(P43:AA43)=0,0,V43/SUM(P43:AA43)*Assumptions!$G$11) -> 0 | W44: =IF(SUM(P43:AA43)=0,0,W43/SUM(P43:AA43)*Assumptions!$G$11) -> 0 | X44: =IF(SUM(P43:AA43)=0,0,X43/SUM(P43:AA43)*Assumptions!$G$11) -> 2 | Y44: =IF(SUM(P43:AA43)=0,0,Y43/SUM(P43:AA43)*Assumptions!$G$11) -> 2 | Z44: =IF(SUM(P43:AA43)=0,0,Z43/SUM(P43:AA43)*Assumptions!$G$11) -> 2 | AA44: =IF(SUM(P43:AA43)=0,0,AA43/SUM(P43:AA43)*Assumptions!$G$11) -> 1 | AB44: =IF(SUM(AB43:AM43)=0,0,AB43/SUM(AB43:AM43)*Assumptions!$G$12) -> 1 | AC44: =IF(SUM(AB43:AM43)=0,0,AC43/SUM(AB43:AM43)*Assumptions!$G$12) -> 1 | AD44: =IF(SUM(AB43:AM43)=0,0,AD43/SUM(AB43:AM43)*Assumptions!$G$12) -> 2 | AE44: =IF(SUM(AB43:AM43)=0,0,AE43/SUM(AB43:AM43)*Assumptions!$G$12) -> 3 | AF44: =IF(SUM(AB43:AM43)=0,0,AF43/SUM(AB43:AM43)*Assumptions!$G$12) -> 3 | AG44: =IF(SUM(AB43:AM43)=0,0,AG43/SUM(AB43:AM43)*Assumptions!$G$12) -> 3 | AH44: =IF(SUM(AB43:AM43)=0,0,AH43/SUM(AB43:AM43)*Assumptions!$G$12) -> 0 | AI44: =IF(SUM(AB43:AM43)=0,0,AI43/SUM(AB43:AM43)*Assumptions!$G$12) -> 0 | AJ44: =IF(SUM(AB43:AM43)=0,0,AJ43/SUM(AB43:AM43)*Assumptions!$G$12) -> 3 | AK44: =IF(SUM(AB43:AM43)=0,0,AK43/SUM(AB43:AM43)*Assumptions!$G$12) -> 3 | AL44: =IF(SUM(AB43:AM43)=0,0,AL43/SUM(AB43:AM43)*Assumptions!$G$12) -> 3 | AM44: =IF(SUM(AB43:AM43)=0,0,AM43/SUM(AB43:AM43)*Assumptions!$G$12) -> 2
C45: 机构服务收入 | D45: =D44*Assumptions!$G$13 -> 0 | E45: =E44*Assumptions!$G$13 -> 0 | F45: =F44*Assumptions!$G$13 -> 22000 | G45: =G44*Assumptions!$G$13 -> 0 | H45: =H44*Assumptions!$G$13 -> 22000 | I45: =I44*Assumptions!$G$13 -> 22000 | J45: =J44*Assumptions!$G$13 -> 0 | K45: =K44*Assumptions!$G$13 -> 0 | ... AM45: =AM44*Assumptions!$G$13 -> 44000
C46: 当月收款 | D46: =D45*Assumptions!$G$28 -> 0 | E46: =E45*Assumptions!$G$28+D47 -> 0 | F46: =F45*Assumptions!$G$28+E47 -> 11000 | G46: =G45*Assumptions!$G$28+F47 -> 11000 | H46: =H45*Assumptions!$G$28+G47 -> 11000 | I46: =I45*Assumptions!$G$28+H47 -> 22000 | J46: =J45*Assumptions!$G$28+I47 -> 11000 | K46: =K45*Assumptions!$G$28+J47 -> 0 | L46: =L45*Assumptions!$G$28+K47 -> 11000 | ... AM46: =AM45*Assumptions!$G$28+AL47 -> 55000
C47: 期末应收 | D47: =D45*(1-Assumptions!$G$28) -> 0 | E47: =E45*(1-Assumptions!$G$28) -> 0 | F47: =F45*(1-Assumptions!$G$28) -> 11000 | G47: =G45*(1-Assumptions!$G$28) -> 0 | H47: =H45*(1-Assumptions!$G$28) -> 11000 | I47: =I45*(1-Assumptions!$G$28) -> 11000 | J47: =J45*(1-Assumptions!$G$28) -> 0 | K47: =K45*(1-Assumptions!$G$28) -> 0 | ... AM47: =AM45*(1-Assumptions!$G$28) -> 22000
C48: 交付工时 | D48: =D44*Assumptions!$G$14 -> 0 | E48: =E44*Assumptions!$G$14 -> 0 | F48: =F44*Assumptions!$G$14 -> 70 | G48: =G44*Assumptions!$G$14 -> 0 | H48: =H44*Assumptions!$G$14 -> 70 | I48: =I44*Assumptions!$G$14 -> 70 | J48: =J44*Assumptions!$G$14 -> 0 | K48: =K44*Assumptions!$G$14 -> 0 | ... AM48: =AM44*Assumptions!$G$14 -> 140
C49: 内部交付工时 | D49: =MIN(D48,MAX(0,Assumptions!$G$30-Assumptions!$G$31)) -> 0 | E49: =MIN(E48,MAX(0,Assumptions!$G$30-Assumptions!$G$31)) -> 0 | F49: =MIN(F48,MAX(0,Assumptions!$G$30-Assumptions!$G$31)) -> 70 | G49: =MIN(G48,MAX(0,Assumptions!$G$30-Assumptions!$G$31)) -> 0 | H49: =MIN(H48,MAX(0,Assumptions!$G$30-Assumptions!$G$31)) -> 70 | I49: =MIN(I48,MAX(0,Assumptions!$G$30-Assumptions!$G$31)) -> 70 | J49: =MIN(J48,MAX(0,Assumptions!$G$30-Assumptions!$G$31)) -> 0 | K49: =MIN(K48,MAX(0,Assumptions!$G$30-Assumptions!$G$31)) -> 0 | ... AM49: =MIN(AM48,MAX(0,Assumptions!$G$30-Assumptions!$G$31)) -> 80
C50: 外部增援工时 | D50: =MAX(0,D48-D49) -> 0 | E50: =MAX(0,E48-E49) -> 0 | F50: =MAX(0,F48-F49) -> 0 | G50: =MAX(0,G48-G49) -> 0 | H50: =MAX(0,H48-H49) -> 0 | I50: =MAX(0,I48-I49) -> 0 | J50: =MAX(0,J48-J49) -> 0 | K50: =MAX(0,K48-K49) -> 0 | ... AM50: =MAX(0,AM48-AM49) -> 60
C51: 交付能力余量 | D51: =MAX(0,Assumptions!$G$30-Assumptions!$G$31)+Assumptions!$G$32-D48 -> 240 | E51: =MAX(0,Assumptions!$G$30-Assumptions!$G$31)+Assumptions!$G$32-E48 -> 240 | F51: =MAX(0,Assumptions!$G$30-Assumptions!$G$31)+Assumptions!$G$32-F48 -> 170 | G51: =MAX(0,Assumptions!$G$30-Assumptions!$G$31)+Assumptions!$G$32-G48 -> 240 | H51: =MAX(0,Assumptions!$G$30-Assumptions!$G$31)+Assumptions!$G$32-H48 -> 170 | I51: =MAX(0,Assumptions!$G$30-Assumptions!$G$31)+Assumptions!$G$32-I48 -> 170 | J51: =MAX(0,Assumptions!$G$30-Assumptions!$G$31)+Assumptions!$G$32-J48 -> 240 | K51: =MAX(0,Assumptions!$G$30-Assumptions!$G$31)+Assumptions!$G$32-K48 -> 240 | ... AM51: =MAX(0,Assumptions!$G$30-Assumptions!$G$31)+Assumptions!$G$32-AM48 -> 100
C52: 合同分配整数差额 | D52: =ABS(D44-ROUND(D44,0)) -> 0 | E52: =ABS(E44-ROUND(E44,0)) -> 0 | F52: =ABS(F44-ROUND(F44,0)) -> 0 | G52: =ABS(G44-ROUND(G44,0)) -> 0 | H52: =ABS(H44-ROUND(H44,0)) -> 0 | I52: =ABS(I44-ROUND(I44,0)) -> 0 | J52: =ABS(J44-ROUND(J44,0)) -> 0 | K52: =ABS(K44-ROUND(K44,0)) -> 0 | ... AM52: =ABS(AM44-ROUND(AM44,0)) -> 0

Sheet Costs
C2: Blocky | 成本与工时
C3: 人民币 · 2027–2029示例测算
C6: 基准 | D6: 46388 | E6: 46419 | F6: 46447 | G6: 46478 | H6: 46508 | I6: 46539 | J6: 46569 | K6: 46600 | L6: 46631 | M6: 46661 | N6: 46692 | O6: 46722 | P6: 46753 | Q6: 46784 | R6: 46813 | S6: 46844 | T6: 46874 | U6: 46905 | V6: 46935 | W6: 46966 | X6: 46997 | Y6: 47027 | Z6: 47058 | AA6: 47088 | AB6: 47119 | AC6: 47150 | AD6: 47178 | AE6: 47209 | AF6: 47239 | AG6: 47270 | AH6: 47300 | AI6: 47331 | AJ6: 47362 | AK6: 47392 | AL6: 47423 | AM6: 47453
C7: 模型预算 | D7: =Revenue!D8*(Assumptions!$E$17*Assumptions!$E$19+Assumptions!$E$18*Assumptions!$E$20) -> 0 | E7: =Revenue!E8*(Assumptions!$E$17*Assumptions!$E$19+Assumptions!$E$18*Assumptions!$E$20) -> 0 | F7: =Revenue!F8*(Assumptions!$E$17*Assumptions!$E$19+Assumptions!$E$18*Assumptions!$E$20) -> 0 | G7: =Revenue!G8*(Assumptions!$E$17*Assumptions!$E$19+Assumptions!$E$18*Assumptions!$E$20) -> 1400 | H7: =Revenue!H8*(Assumptions!$E$17*Assumptions!$E$19+Assumptions!$E$18*Assumptions!$E$20) -> 0 | I7: =Revenue!I8*(Assumptions!$E$17*Assumptions!$E$19+Assumptions!$E$18*Assumptions!$E$20) -> 1400 | J7: =Revenue!J8*(Assumptions!$E$17*Assumptions!$E$19+Assumptions!$E$18*Assumptions!$E$20) -> 0 | K7: =Revenue!K8*(Assumptions!$E$17*Assumptions!$E$19+Assumptions!$E$18*Assumptions!$E$20) -> 0 | ... AM7: =Revenue!AM8*(Assumptions!$E$17*Assumptions!$E$19+Assumptions!$E$18*Assumptions!$E$20) -> 1400
C8: 内部交付报酬 | D8: =Revenue!D13*Assumptions!$E$15 -> 0 | E8: =Revenue!E13*Assumptions!$E$15 -> 0 | F8: =Revenue!F13*Assumptions!$E$15 -> 0 | G8: =Revenue!G13*Assumptions!$E$15 -> 6400 | H8: =Revenue!H13*Assumptions!$E$15 -> 0 | I8: =Revenue!I13*Assumptions!$E$15 -> 6400 | J8: =Revenue!J13*Assumptions!$E$15 -> 0 | K8: =Revenue!K13*Assumptions!$E$15 -> 0 | ... AM8: =Revenue!AM13*Assumptions!$E$15 -> 6400
C9: 外部增援预算 | D9: =Revenue!D14*Assumptions!$E$16 -> 0 | E9: =Revenue!E14*Assumptions!$E$16 -> 0 | F9: =Revenue!F14*Assumptions!$E$16 -> 0 | G9: =Revenue!G14*Assumptions!$E$16 -> 0 | H9: =Revenue!H14*Assumptions!$E$16 -> 0 | I9: =Revenue!I14*Assumptions!$E$16 -> 0 | J9: =Revenue!J14*Assumptions!$E$16 -> 0 | K9: =Revenue!K14*Assumptions!$E$16 -> 0 | ... AM9: =Revenue!AM14*Assumptions!$E$16 -> 0
C10: 其他直接费用 | D10: =Revenue!D8*Assumptions!$E$21 -> 0 | E10: =Revenue!E8*Assumptions!$E$21 -> 0 | F10: =Revenue!F8*Assumptions!$E$21 -> 0 | G10: =Revenue!G8*Assumptions!$E$21 -> 600 | H10: =Revenue!H8*Assumptions!$E$21 -> 0 | I10: =Revenue!I8*Assumptions!$E$21 -> 600 | J10: =Revenue!J8*Assumptions!$E$21 -> 0 | K10: =Revenue!K8*Assumptions!$E$21 -> 0 | ... AM10: =Revenue!AM8*Assumptions!$E$21 -> 600
C11: 直接成本小计 | D11: =SUM(D7:D10) -> 0 | E11: =SUM(E7:E10) -> 0 | F11: =SUM(F7:F10) -> 0 | G11: =SUM(G7:G10) -> 8400 | H11: =SUM(H7:H10) -> 0 | I11: =SUM(I7:I10) -> 8400 | J11: =SUM(J7:J10) -> 0 | K11: =SUM(K7:K10) -> 0 | ... AM11: =SUM(AM7:AM10) -> 8400
C12: 固定核心报酬 | D12: =Assumptions!$E$22 -> 6000 | E12: =Assumptions!$E$22 -> 6000 | F12: =Assumptions!$E$22 -> 6000 | G12: =Assumptions!$E$22 -> 6000 | H12: =Assumptions!$E$22 -> 6000 | I12: =Assumptions!$E$22 -> 6000 | J12: =Assumptions!$E$22 -> 6000 | K12: =Assumptions!$E$22 -> 6000 | ... AM12: =Assumptions!$E$22 -> 6000
C13: 固定运营费 | D13: =Assumptions!$E$23 -> 1800 | E13: =Assumptions!$E$23 -> 1800 | F13: =Assumptions!$E$23 -> 1800 | G13: =Assumptions!$E$23 -> 1800 | H13: =Assumptions!$E$23 -> 1800 | I13: =Assumptions!$E$23 -> 1800 | J13: =Assumptions!$E$23 -> 1800 | K13: =Assumptions!$E$23 -> 1800 | ... AM13: =Assumptions!$E$23 -> 1800
C14: 税费现金预算预留 | D14: =Revenue!D9*Assumptions!$E$29 -> 0 | E14: =Revenue!E9*Assumptions!$E$29 -> 0 | F14: =Revenue!F9*Assumptions!$E$29 -> 0 | G14: =Revenue!G9*Assumptions!$E$29 -> 360 | H14: =Revenue!H9*Assumptions!$E$29 -> 0 | I14: =Revenue!I9*Assumptions!$E$29 -> 360 | J14: =Revenue!J9*Assumptions!$E$29 -> 0 | K14: =Revenue!K9*Assumptions!$E$29 -> 0 | ... AM14: =Revenue!AM9*Assumptions!$E$29 -> 360
C15: 设备资本支出 | D15: =Assumptions!$E$24 -> 12000 | E15: =0 -> 0 | F15: =0 -> 0 | G15: =0 -> 0 | H15: =0 -> 0 | I15: =0 -> 0 | J15: =0 -> 0 | K15: =0 -> 0 | L15: =0 -> 0 | ... AM15: =0 -> 0
C16: 设备折旧 | D16: =IF(0<Assumptions!$E$25,Assumptions!$E$24/Assumptions!$E$25,0) -> 333.33333 | E16: =IF(1<Assumptions!$E$25,Assumptions!$E$24/Assumptions!$E$25,0) -> 333.33333 | F16: =IF(2<Assumptions!$E$25,Assumptions!$E$24/Assumptions!$E$25,0) -> 333.33333 | G16: =IF(3<Assumptions!$E$25,Assumptions!$E$24/Assumptions!$E$25,0) -> 333.33333 | H16: =IF(4<Assumptions!$E$25,Assumptions!$E$24/Assumptions!$E$25,0) -> 333.33333 | I16: =IF(5<Assumptions!$E$25,Assumptions!$E$24/Assumptions!$E$25,0) -> 333.33333 | J16: =IF(6<Assumptions!$E$25,Assumptions!$E$24/Assumptions!$E$25,0) -> 333.33333 | K16: =IF(7<Assumptions!$E$25,Assumptions!$E$24/Assumptions!$E$25,0) -> 333.33333 | L16: =IF(8<Assumptions!$E$25,Assumptions!$E$24/Assumptions!$E$25,0) -> 333.33333 | M16: =IF(9<Assumptions!$E$25,Assumptions!$E$24/Assumptions!$E$25,0) -> 333.33333 | N16: =IF(10<Assumptions!$E$25,Assumptions!$E$24/Assumptions!$E$25,0) -> 333.33333 | O16: =IF(11<Assumptions!$E$25,Assumptions!$E$24/Assumptions!$E$25,0) -> 333.33333 | P16: =IF(12<Assumptions!$E$25,Assumptions!$E$24/Assumptions!$E$25,0) -> 333.33333 | Q16: =IF(13<Assumptions!$E$25,Assumptions!$E$24/Assumptions!$E$25,0) -> 333.33333 | R16: =IF(14<Assumptions!$E$25,Assumptions!$E$24/Assumptions!$E$25,0) -> 333.33333 | S16: =IF(15<Assumptions!$E$25,Assumptions!$E$24/Assumptions!$E$25,0) -> 333.33333 | T16: =IF(16<Assumptions!$E$25,Assumptions!$E$24/Assumptions!$E$25,0) -> 333.33333 | U16: =IF(17<Assumptions!$E$25,Assumptions!$E$24/Assumptions!$E$25,0) -> 333.33333 | V16: =IF(18<Assumptions!$E$25,Assumptions!$E$24/Assumptions!$E$25,0) -> 333.33333 | W16: =IF(19<Assumptions!$E$25,Assumptions!$E$24/Assumptions!$E$25,0) -> 333.33333 | X16: =IF(20<Assumptions!$E$25,Assumptions!$E$24/Assumptions!$E$25,0) -> 333.33333 | Y16: =IF(21<Assumptions!$E$25,Assumptions!$E$24/Assumptions!$E$25,0) -> 333.33333 | Z16: =IF(22<Assumptions!$E$25,Assumptions!$E$24/Assumptions!$E$25,0) -> 333.33333 | AA16: =IF(23<Assumptions!$E$25,Assumptions!$E$24/Assumptions!$E$25,0) -> 333.33333 | AB16: =IF(24<Assumptions!$E$25,Assumptions!$E$24/Assumptions!$E$25,0) -> 333.33333 | AC16: =IF(25<Assumptions!$E$25,Assumptions!$E$24/Assumptions!$E$25,0) -> 333.33333 | AD16: =IF(26<Assumptions!$E$25,Assumptions!$E$24/Assumptions!$E$25,0) -> 333.33333 | AE16: =IF(27<Assumptions!$E$25,Assumptions!$E$24/Assumptions!$E$25,0) -> 333.33333 | AF16: =IF(28<Assumptions!$E$25,Assumptions!$E$24/Assumptions!$E$25,0) -> 333.33333 | AG16: =IF(29<Assumptions!$E$25,Assumptions!$E$24/Assumptions!$E$25,0) -> 333.33333 | AH16: =IF(30<Assumptions!$E$25,Assumptions!$E$24/Assumptions!$E$25,0) -> 333.33333 | AI16: =IF(31<Assumptions!$E$25,Assumptions!$E$24/Assumptions!$E$25,0) -> 333.33333 | AJ16: =IF(32<Assumptions!$E$25,Assumptions!$E$24/Assumptions!$E$25,0) -> 333.33333 | AK16: =IF(33<Assumptions!$E$25,Assumptions!$E$24/Assumptions!$E$25,0) -> 333.33333 | AL16: =IF(34<Assumptions!$E$25,Assumptions!$E$24/Assumptions!$E$25,0) -> 333.33333 | AM16: =IF(35<Assumptions!$E$25,Assumptions!$E$24/Assumptions!$E$25,0) -> 333.33333
C17: 总费用（含折旧） | D17: =D11+SUM(D12:D14)+D16 -> 8133.3333 | E17: =E11+SUM(E12:E14)+E16 -> 8133.3333 | F17: =F11+SUM(F12:F14)+F16 -> 8133.3333 | G17: =G11+SUM(G12:G14)+G16 -> 16893.333 | H17: =H11+SUM(H12:H14)+H16 -> 8133.3333 | I17: =I11+SUM(I12:I14)+I16 -> 16893.333 | J17: =J11+SUM(J12:J14)+J16 -> 8133.3333 | K17: =K11+SUM(K12:K14)+K16 -> 8133.3333 | ... AM17: =AM11+SUM(AM12:AM14)+AM16 -> 16893.333
C18: 现金费用（不含折旧） | D18: =D17-D16 -> 7800 | E18: =E17-E16 -> 7800 | F18: =F17-F16 -> 7800 | G18: =G17-G16 -> 16560 | H18: =H17-H16 -> 7800 | I18: =I17-I16 -> 16560 | J18: =J17-J16 -> 7800 | K18: =K17-K16 -> 7800 | ... AM18: =AM17-AM16 -> 16560
C19: 经营损益 | D19: =Revenue!D9-D17 -> -8133.3333 | E19: =Revenue!E9-E17 -> -8133.3333 | F19: =Revenue!F9-F17 -> -8133.3333 | G19: =Revenue!G9-G17 -> 1106.6667 | H19: =Revenue!H9-H17 -> -8133.3333 | I19: =Revenue!I9-I17 -> 1106.6667 | J19: =Revenue!J9-J17 -> -8133.3333 | K19: =Revenue!K9-K17 -> -8133.3333 | ... AM19: =Revenue!AM9-AM17 -> 1106.6667
C20: 固定核心工时 | D20: =Assumptions!$E$31 -> 160 | E20: =Assumptions!$E$31 -> 160 | F20: =Assumptions!$E$31 -> 160 | G20: =Assumptions!$E$31 -> 160 | H20: =Assumptions!$E$31 -> 160 | I20: =Assumptions!$E$31 -> 160 | J20: =Assumptions!$E$31 -> 160 | K20: =Assumptions!$E$31 -> 160 | ... AM20: =Assumptions!$E$31 -> 160
C21: 内部可用交付工时 | D21: =MAX(0,Assumptions!$E$30-Assumptions!$E$31) -> 80 | E21: =MAX(0,Assumptions!$E$30-Assumptions!$E$31) -> 80 | F21: =MAX(0,Assumptions!$E$30-Assumptions!$E$31) -> 80 | G21: =MAX(0,Assumptions!$E$30-Assumptions!$E$31) -> 80 | H21: =MAX(0,Assumptions!$E$30-Assumptions!$E$31) -> 80 | I21: =MAX(0,Assumptions!$E$30-Assumptions!$E$31) -> 80 | J21: =MAX(0,Assumptions!$E$30-Assumptions!$E$31) -> 80 | K21: =MAX(0,Assumptions!$E$30-Assumptions!$E$31) -> 80 | ... AM21: =MAX(0,Assumptions!$E$30-Assumptions!$E$31) -> 80
C22: 外部增援上限 | D22: =Assumptions!$E$32 -> 160 | E22: =Assumptions!$E$32 -> 160 | F22: =Assumptions!$E$32 -> 160 | G22: =Assumptions!$E$32 -> 160 | H22: =Assumptions!$E$32 -> 160 | I22: =Assumptions!$E$32 -> 160 | J22: =Assumptions!$E$32 -> 160 | K22: =Assumptions!$E$32 -> 160 | ... AM22: =Assumptions!$E$32 -> 160
C30: 悲观 | D30: 46388 | E30: 46419 | F30: 46447 | G30: 46478 | H30: 46508 | I30: 46539 | J30: 46569 | K30: 46600 | L30: 46631 | M30: 46661 | N30: 46692 | O30: 46722 | P30: 46753 | Q30: 46784 | R30: 46813 | S30: 46844 | T30: 46874 | U30: 46905 | V30: 46935 | W30: 46966 | X30: 46997 | Y30: 47027 | Z30: 47058 | AA30: 47088 | AB30: 47119 | AC30: 47150 | AD30: 47178 | AE30: 47209 | AF30: 47239 | AG30: 47270 | AH30: 47300 | AI30: 47331 | AJ30: 47362 | AK30: 47392 | AL30: 47423 | AM30: 47453
C31: 模型预算 | D31: =Revenue!D26*(Assumptions!$F$17*Assumptions!$F$19+Assumptions!$F$18*Assumptions!$F$20) -> 0 | E31: =Revenue!E26*(Assumptions!$F$17*Assumptions!$F$19+Assumptions!$F$18*Assumptions!$F$20) -> 0 | F31: =Revenue!F26*(Assumptions!$F$17*Assumptions!$F$19+Assumptions!$F$18*Assumptions!$F$20) -> 0 | G31: =Revenue!G26*(Assumptions!$F$17*Assumptions!$F$19+Assumptions!$F$18*Assumptions!$F$20) -> 0 | H31: =Revenue!H26*(Assumptions!$F$17*Assumptions!$F$19+Assumptions!$F$18*Assumptions!$F$20) -> 3150 | I31: =Revenue!I26*(Assumptions!$F$17*Assumptions!$F$19+Assumptions!$F$18*Assumptions!$F$20) -> 0 | J31: =Revenue!J26*(Assumptions!$F$17*Assumptions!$F$19+Assumptions!$F$18*Assumptions!$F$20) -> 0 | K31: =Revenue!K26*(Assumptions!$F$17*Assumptions!$F$19+Assumptions!$F$18*Assumptions!$F$20) -> 0 | ... AM31: =Revenue!AM26*(Assumptions!$F$17*Assumptions!$F$19+Assumptions!$F$18*Assumptions!$F$20) -> 0
C32: 内部交付报酬 | D32: =Revenue!D31*Assumptions!$F$15 -> 0 | E32: =Revenue!E31*Assumptions!$F$15 -> 0 | F32: =Revenue!F31*Assumptions!$F$15 -> 0 | G32: =Revenue!G31*Assumptions!$F$15 -> 0 | H32: =Revenue!H31*Assumptions!$F$15 -> 7200 | I32: =Revenue!I31*Assumptions!$F$15 -> 0 | J32: =Revenue!J31*Assumptions!$F$15 -> 0 | K32: =Revenue!K31*Assumptions!$F$15 -> 0 | ... AM32: =Revenue!AM31*Assumptions!$F$15 -> 0
C33: 外部增援预算 | D33: =Revenue!D32*Assumptions!$F$16 -> 0 | E33: =Revenue!E32*Assumptions!$F$16 -> 0 | F33: =Revenue!F32*Assumptions!$F$16 -> 0 | G33: =Revenue!G32*Assumptions!$F$16 -> 0 | H33: =Revenue!H32*Assumptions!$F$16 -> 2200 | I33: =Revenue!I32*Assumptions!$F$16 -> 0 | J33: =Revenue!J32*Assumptions!$F$16 -> 0 | K33: =Revenue!K32*Assumptions!$F$16 -> 0 | ... AM33: =Revenue!AM32*Assumptions!$F$16 -> 0
C34: 其他直接费用 | D34: =Revenue!D26*Assumptions!$F$21 -> 0 | E34: =Revenue!E26*Assumptions!$F$21 -> 0 | F34: =Revenue!F26*Assumptions!$F$21 -> 0 | G34: =Revenue!G26*Assumptions!$F$21 -> 0 | H34: =Revenue!H26*Assumptions!$F$21 -> 800 | I34: =Revenue!I26*Assumptions!$F$21 -> 0 | J34: =Revenue!J26*Assumptions!$F$21 -> 0 | K34: =Revenue!K26*Assumptions!$F$21 -> 0 | ... AM34: =Revenue!AM26*Assumptions!$F$21 -> 0
C35: 直接成本小计 | D35: =SUM(D31:D34) -> 0 | E35: =SUM(E31:E34) -> 0 | F35: =SUM(F31:F34) -> 0 | G35: =SUM(G31:G34) -> 0 | H35: =SUM(H31:H34) -> 13350 | I35: =SUM(I31:I34) -> 0 | J35: =SUM(J31:J34) -> 0 | K35: =SUM(K31:K34) -> 0 | ... AM35: =SUM(AM31:AM34) -> 0
C36: 固定核心报酬 | D36: =Assumptions!$F$22 -> 6000 | E36: =Assumptions!$F$22 -> 6000 | F36: =Assumptions!$F$22 -> 6000 | G36: =Assumptions!$F$22 -> 6000 | H36: =Assumptions!$F$22 -> 6000 | I36: =Assumptions!$F$22 -> 6000 | J36: =Assumptions!$F$22 -> 6000 | K36: =Assumptions!$F$22 -> 6000 | ... AM36: =Assumptions!$F$22 -> 6000
C37: 固定运营费 | D37: =Assumptions!$F$23 -> 1800 | E37: =Assumptions!$F$23 -> 1800 | F37: =Assumptions!$F$23 -> 1800 | G37: =Assumptions!$F$23 -> 1800 | H37: =Assumptions!$F$23 -> 1800 | I37: =Assumptions!$F$23 -> 1800 | J37: =Assumptions!$F$23 -> 1800 | K37: =Assumptions!$F$23 -> 1800 | ... AM37: =Assumptions!$F$23 -> 1800
C38: 税费现金预算预留 | D38: =Revenue!D27*Assumptions!$F$29 -> 0 | E38: =Revenue!E27*Assumptions!$F$29 -> 0 | F38: =Revenue!F27*Assumptions!$F$29 -> 0 | G38: =Revenue!G27*Assumptions!$F$29 -> 0 | H38: =Revenue!H27*Assumptions!$F$29 -> 450 | I38: =Revenue!I27*Assumptions!$F$29 -> 0 | J38: =Revenue!J27*Assumptions!$F$29 -> 0 | K38: =Revenue!K27*Assumptions!$F$29 -> 0 | ... AM38: =Revenue!AM27*Assumptions!$F$29 -> 0
C39: 设备资本支出 | D39: =Assumptions!$F$24 -> 12000 | E39: =0 -> 0 | F39: =0 -> 0 | G39: =0 -> 0 | H39: =0 -> 0 | I39: =0 -> 0 | J39: =0 -> 0 | K39: =0 -> 0 | L39: =0 -> 0 | ... AM39: =0 -> 0
C40: 设备折旧 | D40: =IF(0<Assumptions!$F$25,Assumptions!$F$24/Assumptions!$F$25,0) -> 333.33333 | E40: =IF(1<Assumptions!$F$25,Assumptions!$F$24/Assumptions!$F$25,0) -> 333.33333 | F40: =IF(2<Assumptions!$F$25,Assumptions!$F$24/Assumptions!$F$25,0) -> 333.33333 | G40: =IF(3<Assumptions!$F$25,Assumptions!$F$24/Assumptions!$F$25,0) -> 333.33333 | H40: =IF(4<Assumptions!$F$25,Assumptions!$F$24/Assumptions!$F$25,0) -> 333.33333 | I40: =IF(5<Assumptions!$F$25,Assumptions!$F$24/Assumptions!$F$25,0) -> 333.33333 | J40: =IF(6<Assumptions!$F$25,Assumptions!$F$24/Assumptions!$F$25,0) -> 333.33333 | K40: =IF(7<Assumptions!$F$25,Assumptions!$F$24/Assumptions!$F$25,0) -> 333.33333 | L40: =IF(8<Assumptions!$F$25,Assumptions!$F$24/Assumptions!$F$25,0) -> 333.33333 | M40: =IF(9<Assumptions!$F$25,Assumptions!$F$24/Assumptions!$F$25,0) -> 333.33333 | N40: =IF(10<Assumptions!$F$25,Assumptions!$F$24/Assumptions!$F$25,0) -> 333.33333 | O40: =IF(11<Assumptions!$F$25,Assumptions!$F$24/Assumptions!$F$25,0) -> 333.33333 | P40: =IF(12<Assumptions!$F$25,Assumptions!$F$24/Assumptions!$F$25,0) -> 333.33333 | Q40: =IF(13<Assumptions!$F$25,Assumptions!$F$24/Assumptions!$F$25,0) -> 333.33333 | R40: =IF(14<Assumptions!$F$25,Assumptions!$F$24/Assumptions!$F$25,0) -> 333.33333 | S40: =IF(15<Assumptions!$F$25,Assumptions!$F$24/Assumptions!$F$25,0) -> 333.33333 | T40: =IF(16<Assumptions!$F$25,Assumptions!$F$24/Assumptions!$F$25,0) -> 333.33333 | U40: =IF(17<Assumptions!$F$25,Assumptions!$F$24/Assumptions!$F$25,0) -> 333.33333 | V40: =IF(18<Assumptions!$F$25,Assumptions!$F$24/Assumptions!$F$25,0) -> 333.33333 | W40: =IF(19<Assumptions!$F$25,Assumptions!$F$24/Assumptions!$F$25,0) -> 333.33333 | X40: =IF(20<Assumptions!$F$25,Assumptions!$F$24/Assumptions!$F$25,0) -> 333.33333 | Y40: =IF(21<Assumptions!$F$25,Assumptions!$F$24/Assumptions!$F$25,0) -> 333.33333 | Z40: =IF(22<Assumptions!$F$25,Assumptions!$F$24/Assumptions!$F$25,0) -> 333.33333 | AA40: =IF(23<Assumptions!$F$25,Assumptions!$F$24/Assumptions!$F$25,0) -> 333.33333 | AB40: =IF(24<Assumptions!$F$25,Assumptions!$F$24/Assumptions!$F$25,0) -> 333.33333 | AC40: =IF(25<Assumptions!$F$25,Assumptions!$F$24/Assumptions!$F$25,0) -> 333.33333 | AD40: =IF(26<Assumptions!$F$25,Assumptions!$F$24/Assumptions!$F$25,0) -> 333.33333 | AE40: =IF(27<Assumptions!$F$25,Assumptions!$F$24/Assumptions!$F$25,0) -> 333.33333 | AF40: =IF(28<Assumptions!$F$25,Assumptions!$F$24/Assumptions!$F$25,0) -> 333.33333 | AG40: =IF(29<Assumptions!$F$25,Assumptions!$F$24/Assumptions!$F$25,0) -> 333.33333 | AH40: =IF(30<Assumptions!$F$25,Assumptions!$F$24/Assumptions!$F$25,0) -> 333.33333 | AI40: =IF(31<Assumptions!$F$25,Assumptions!$F$24/Assumptions!$F$25,0) -> 333.33333 | AJ40: =IF(32<Assumptions!$F$25,Assumptions!$F$24/Assumptions!$F$25,0) -> 333.33333 | AK40: =IF(33<Assumptions!$F$25,Assumptions!$F$24/Assumptions!$F$25,0) -> 333.33333 | AL40: =IF(34<Assumptions!$F$25,Assumptions!$F$24/Assumptions!$F$25,0) -> 333.33333 | AM40: =IF(35<Assumptions!$F$25,Assumptions!$F$24/Assumptions!$F$25,0) -> 333.33333
C41: 总费用（含折旧） | D41: =D35+SUM(D36:D38)+D40 -> 8133.3333 | E41: =E35+SUM(E36:E38)+E40 -> 8133.3333 | F41: =F35+SUM(F36:F38)+F40 -> 8133.3333 | G41: =G35+SUM(G36:G38)+G40 -> 8133.3333 | H41: =H35+SUM(H36:H38)+H40 -> 21933.333 | I41: =I35+SUM(I36:I38)+I40 -> 8133.3333 | J41: =J35+SUM(J36:J38)+J40 -> 8133.3333 | K41: =K35+SUM(K36:K38)+K40 -> 8133.3333 | ... AM41: =AM35+SUM(AM36:AM38)+AM40 -> 8133.3333
C42: 现金费用（不含折旧） | D42: =D41-D40 -> 7800 | E42: =E41-E40 -> 7800 | F42: =F41-F40 -> 7800 | G42: =G41-G40 -> 7800 | H42: =H41-H40 -> 21600 | I42: =I41-I40 -> 7800 | J42: =J41-J40 -> 7800 | K42: =K41-K40 -> 7800 | ... AM42: =AM41-AM40 -> 7800
C43: 经营损益 | D43: =Revenue!D27-D41 -> -8133.3333 | E43: =Revenue!E27-E41 -> -8133.3333 | F43: =Revenue!F27-F41 -> -8133.3333 | G43: =Revenue!G27-G41 -> -8133.3333 | H43: =Revenue!H27-H41 -> -6933.3333 | I43: =Revenue!I27-I41 -> -8133.3333 | J43: =Revenue!J27-J41 -> -8133.3333 | K43: =Revenue!K27-K41 -> -8133.3333 | ... AM43: =Revenue!AM27-AM41 -> -8133.3333
C44: 固定核心工时 | D44: =Assumptions!$F$31 -> 160 | E44: =Assumptions!$F$31 -> 160 | F44: =Assumptions!$F$31 -> 160 | G44: =Assumptions!$F$31 -> 160 | H44: =Assumptions!$F$31 -> 160 | I44: =Assumptions!$F$31 -> 160 | J44: =Assumptions!$F$31 -> 160 | K44: =Assumptions!$F$31 -> 160 | ... AM44: =Assumptions!$F$31 -> 160
C45: 内部可用交付工时 | D45: =MAX(0,Assumptions!$F$30-Assumptions!$F$31) -> 80 | E45: =MAX(0,Assumptions!$F$30-Assumptions!$F$31) -> 80 | F45: =MAX(0,Assumptions!$F$30-Assumptions!$F$31) -> 80 | G45: =MAX(0,Assumptions!$F$30-Assumptions!$F$31) -> 80 | H45: =MAX(0,Assumptions!$F$30-Assumptions!$F$31) -> 80 | I45: =MAX(0,Assumptions!$F$30-Assumptions!$F$31) -> 80 | J45: =MAX(0,Assumptions!$F$30-Assumptions!$F$31) -> 80 | K45: =MAX(0,Assumptions!$F$30-Assumptions!$F$31) -> 80 | ... AM45: =MAX(0,Assumptions!$F$30-Assumptions!$F$31) -> 80
C46: 外部增援上限 | D46: =Assumptions!$F$32 -> 160 | E46: =Assumptions!$F$32 -> 160 | F46: =Assumptions!$F$32 -> 160 | G46: =Assumptions!$F$32 -> 160 | H46: =Assumptions!$F$32 -> 160 | I46: =Assumptions!$F$32 -> 160 | J46: =Assumptions!$F$32 -> 160 | K46: =Assumptions!$F$32 -> 160 | ... AM46: =Assumptions!$F$32 -> 160
C54: 积极 | D54: 46388 | E54: 46419 | F54: 46447 | G54: 46478 | H54: 46508 | I54: 46539 | J54: 46569 | K54: 46600 | L54: 46631 | M54: 46661 | N54: 46692 | O54: 46722 | P54: 46753 | Q54: 46784 | R54: 46813 | S54: 46844 | T54: 46874 | U54: 46905 | V54: 46935 | W54: 46966 | X54: 46997 | Y54: 47027 | Z54: 47058 | AA54: 47088 | AB54: 47119 | AC54: 47150 | AD54: 47178 | AE54: 47209 | AF54: 47239 | AG54: 47270 | AH54: 47300 | AI54: 47331 | AJ54: 47362 | AK54: 47392 | AL54: 47423 | AM54: 47453
C55: 模型预算 | D55: =Revenue!D44*(Assumptions!$G$17*Assumptions!$G$19+Assumptions!$G$18*Assumptions!$G$20) -> 0 | E55: =Revenue!E44*(Assumptions!$G$17*Assumptions!$G$19+Assumptions!$G$18*Assumptions!$G$20) -> 0 | F55: =Revenue!F44*(Assumptions!$G$17*Assumptions!$G$19+Assumptions!$G$18*Assumptions!$G$20) -> 1750 | G55: =Revenue!G44*(Assumptions!$G$17*Assumptions!$G$19+Assumptions!$G$18*Assumptions!$G$20) -> 0 | H55: =Revenue!H44*(Assumptions!$G$17*Assumptions!$G$19+Assumptions!$G$18*Assumptions!$G$20) -> 1750 | I55: =Revenue!I44*(Assumptions!$G$17*Assumptions!$G$19+Assumptions!$G$18*Assumptions!$G$20) -> 1750 | J55: =Revenue!J44*(Assumptions!$G$17*Assumptions!$G$19+Assumptions!$G$18*Assumptions!$G$20) -> 0 | K55: =Revenue!K44*(Assumptions!$G$17*Assumptions!$G$19+Assumptions!$G$18*Assumptions!$G$20) -> 0 | ... AM55: =Revenue!AM44*(Assumptions!$G$17*Assumptions!$G$19+Assumptions!$G$18*Assumptions!$G$20) -> 3500
C56: 内部交付报酬 | D56: =Revenue!D49*Assumptions!$G$15 -> 0 | E56: =Revenue!E49*Assumptions!$G$15 -> 0 | F56: =Revenue!F49*Assumptions!$G$15 -> 5600 | G56: =Revenue!G49*Assumptions!$G$15 -> 0 | H56: =Revenue!H49*Assumptions!$G$15 -> 5600 | I56: =Revenue!I49*Assumptions!$G$15 -> 5600 | J56: =Revenue!J49*Assumptions!$G$15 -> 0 | K56: =Revenue!K49*Assumptions!$G$15 -> 0 | ... AM56: =Revenue!AM49*Assumptions!$G$15 -> 6400
C57: 外部增援预算 | D57: =Revenue!D50*Assumptions!$G$16 -> 0 | E57: =Revenue!E50*Assumptions!$G$16 -> 0 | F57: =Revenue!F50*Assumptions!$G$16 -> 0 | G57: =Revenue!G50*Assumptions!$G$16 -> 0 | H57: =Revenue!H50*Assumptions!$G$16 -> 0 | I57: =Revenue!I50*Assumptions!$G$16 -> 0 | J57: =Revenue!J50*Assumptions!$G$16 -> 0 | K57: =Revenue!K50*Assumptions!$G$16 -> 0 | ... AM57: =Revenue!AM50*Assumptions!$G$16 -> 6000
...

Sheet Income Statement
C2: Blocky Studio | 规划损益
C3: 人民币 · 2027–2029示例测算
C6: 年度情景 | D6: 基准 2027 | E6: 基准 2028 | F6: 基准 2029 | G6: 悲观 2027 | H6: 悲观 2028 | I6: 悲观 2029 | J6: 积极 2027 | K6: 积极 2028 | L6: 积极 2029
C8: 机构服务收入 | D8: =SUM(Revenue!D9:O9) -> 72000 | E8: =SUM(Revenue!P9:AA9) -> 180000 | F8: =SUM(Revenue!AB9:AM9) -> 324000 | G8: =SUM(Revenue!D27:O27) -> 30000 | H8: =SUM(Revenue!P27:AA27) -> 60000 | I8: =SUM(Revenue!AB27:AM27) -> 90000 | J8: =SUM(Revenue!D45:O45) -> 132000 | K8: =SUM(Revenue!P45:AA45) -> 308000 | L8: =SUM(Revenue!AB45:AM45) -> 528000
C9: 直接交付成本 | D9: =SUM(Costs!D11:O11) -> 33600 | E9: =SUM(Costs!P11:AA11) -> 87200 | F9: =SUM(Costs!AB11:AM11) -> 165600 | G9: =SUM(Costs!D35:O35) -> 26700 | H9: =SUM(Costs!P35:AA35) -> 53400 | I9: =SUM(Costs!AB35:AM35) -> 80100 | J9: =SUM(Costs!D59:O59) -> 48300 | K9: =SUM(Costs!P59:AA59) -> 118700 | L9: =SUM(Costs!AB59:AM59) -> 211200
C10: 服务贡献 | D10: =D8-D9 -> 38400 | E10: =E8-E9 -> 92800 | F10: =F8-F9 -> 158400 | G10: =G8-G9 -> 3300 | H10: =H8-H9 -> 6600 | I10: =I8-I9 -> 9900 | J10: =J8-J9 -> 83700 | K10: =K8-K9 -> 189300 | L10: =L8-L9 -> 316800
C11: 固定核心报酬 | D11: =SUM(Costs!D12:O12) -> 72000 | E11: =SUM(Costs!P12:AA12) -> 72000 | F11: =SUM(Costs!AB12:AM12) -> 72000 | G11: =SUM(Costs!D36:O36) -> 72000 | H11: =SUM(Costs!P36:AA36) -> 72000 | I11: =SUM(Costs!AB36:AM36) -> 72000 | J11: =SUM(Costs!D60:O60) -> 96000 | K11: =SUM(Costs!P60:AA60) -> 96000 | L11: =SUM(Costs!AB60:AM60) -> 96000
C12: 固定运营费 | D12: =SUM(Costs!D13:O13) -> 21600 | E12: =SUM(Costs!P13:AA13) -> 21600 | F12: =SUM(Costs!AB13:AM13) -> 21600 | G12: =SUM(Costs!D37:O37) -> 21600 | H12: =SUM(Costs!P37:AA37) -> 21600 | I12: =SUM(Costs!AB37:AM37) -> 21600 | J12: =SUM(Costs!D61:O61) -> 30000 | K12: =SUM(Costs!P61:AA61) -> 30000 | L12: =SUM(Costs!AB61:AM61) -> 30000
C13: 税费预算预留 | D13: =SUM(Costs!D14:O14) -> 1440 | E13: =SUM(Costs!P14:AA14) -> 3600 | F13: =SUM(Costs!AB14:AM14) -> 6480 | G13: =SUM(Costs!D38:O38) -> 900 | H13: =SUM(Costs!P38:AA38) -> 1800 | I13: =SUM(Costs!AB38:AM38) -> 2700 | J13: =SUM(Costs!D62:O62) -> 2640 | K13: =SUM(Costs!P62:AA62) -> 6160 | L13: =SUM(Costs!AB62:AM62) -> 10560
C14: 设备折旧 | D14: =SUM(Costs!D16:O16) -> 4000 | E14: =SUM(Costs!P16:AA16) -> 4000 | F14: =SUM(Costs!AB16:AM16) -> 4000 | G14: =SUM(Costs!D40:O40) -> 4000 | H14: =SUM(Costs!P40:AA40) -> 4000 | I14: =SUM(Costs!AB40:AM40) -> 4000 | J14: =SUM(Costs!D64:O64) -> 4000 | K14: =SUM(Costs!P64:AA64) -> 4000 | L14: =SUM(Costs!AB64:AM64) -> 4000
C15: 总费用 | D15: =D9+SUM(D11:D14) -> 132640 | E15: =E9+SUM(E11:E14) -> 188400 | F15: =F9+SUM(F11:F14) -> 269680 | G15: =G9+SUM(G11:G14) -> 125200 | H15: =H9+SUM(H11:H14) -> 152800 | I15: =I9+SUM(I11:I14) -> 180400 | J15: =J9+SUM(J11:J14) -> 180940 | K15: =K9+SUM(K11:K14) -> 254860 | L15: =L9+SUM(L11:L14) -> 351760
C16: 经营损益 | D16: =D8-D15 -> -60640 | E16: =E8-E15 -> -8400 | F16: =F8-F15 -> 54320 | G16: =G8-G15 -> -95200 | H16: =H8-H15 -> -92800 | I16: =I8-I15 -> -90400 | J16: =J8-J15 -> -48940 | K16: =K8-K15 -> 53140 | L16: =L8-L15 -> 176240

Sheet Balance Sheet
C2: Blocky Studio | 模拟资产负债
C3: 人民币 · 2027–2029示例测算
C6: 年度情景 | D6: 基准 2027 | E6: 基准 2028 | F6: 基准 2029 | G6: 悲观 2027 | H6: 悲观 2028 | I6: 悲观 2029 | J6: 积极 2027 | K6: 积极 2028 | L6: 积极 2029
C8: 现金（假设缺口已覆盖） | D8: ='Cash Flow'!O14 -> 54360 | E8: ='Cash Flow'!AA14 -> 40960 | F8: ='Cash Flow'!AM14 -> 99280 | G8: ='Cash Flow'!O38 -> 197900 | H8: ='Cash Flow'!AA38 -> 109100 | I8: ='Cash Flow'!AM38 -> 22700 | J8: ='Cash Flow'!O62 -> 38490 | K8: ='Cash Flow'!AA62 -> 84630 | L8: ='Cash Flow'!AM62 -> 253870
C9: 应收机构款 | D9: =Revenue!O11 -> 0 | E9: =Revenue!AA11 -> 9000 | F9: =Revenue!AM11 -> 9000 | G9: =Revenue!O29 -> 0 | H9: =Revenue!AA29 -> 0 | I9: =Revenue!AM29 -> 0 | J9: =Revenue!O47 -> 0 | K9: =Revenue!AA47 -> 11000 | L9: =Revenue!AM47 -> 22000
C10: 设备原值 | D10: =Assumptions!$E$24 -> 12000 | E10: =Assumptions!$E$24 -> 12000 | F10: =Assumptions!$E$24 -> 12000 | G10: =Assumptions!$F$24 -> 12000 | H10: =Assumptions!$F$24 -> 12000 | I10: =Assumptions!$F$24 -> 12000 | J10: =Assumptions!$G$24 -> 12000 | K10: =Assumptions!$G$24 -> 12000 | L10: =Assumptions!$G$24 -> 12000
C11: 累计折旧 | D11: =SUM(Costs!D16:O16) -> 4000 | E11: =SUM(Costs!D16:AA16) -> 8000 | F11: =SUM(Costs!D16:AM16) -> 12000 | G11: =SUM(Costs!D40:O40) -> 4000 | H11: =SUM(Costs!D40:AA40) -> 8000 | I11: =SUM(Costs!D40:AM40) -> 12000 | J11: =SUM(Costs!D64:O64) -> 4000 | K11: =SUM(Costs!D64:AA64) -> 8000 | L11: =SUM(Costs!D64:AM64) -> 12000
C12: 设备净值 | D12: =D10-D11 -> 8000 | E12: =E10-E11 -> 4000 | F12: =F10-F11 -> 0 | G12: =G10-G11 -> 8000 | H12: =H10-H11 -> 4000 | I12: =I10-I11 -> 0 | J12: =J10-J11 -> 8000 | K12: =K10-K11 -> 4000 | L12: =L10-L11 -> 0
C13: 资产合计 | D13: =SUM(D8:D9)+D12 -> 62360 | E13: =SUM(E8:E9)+E12 -> 53960 | F13: =SUM(F8:F9)+F12 -> 108280 | G13: =SUM(G8:G9)+G12 -> 205900 | H13: =SUM(H8:H9)+H12 -> 113100 | I13: =SUM(I8:I9)+I12 -> 22700 | J13: =SUM(J8:J9)+J12 -> 46490 | K13: =SUM(K8:K9)+K12 -> 99630 | L13: =SUM(L8:L9)+L12 -> 275870
C15: 负债（本模型无借款） | D15: =0 -> 0 | E15: =0 -> 0 | F15: =0 -> 0 | G15: =0 -> 0 | H15: =0 -> 0 | I15: =0 -> 0 | J15: =0 -> 0 | K15: =0 -> 0 | L15: =0 -> 0
C16: 期初自有资金（未承诺） | D16: =Assumptions!$E$26 -> 20000 | E16: =Assumptions!$E$26 -> 20000 | F16: =Assumptions!$E$26 -> 20000 | G16: =Assumptions!$F$26 -> 20000 | H16: =Assumptions!$F$26 -> 20000 | I16: =Assumptions!$F$26 -> 20000 | J16: =Assumptions!$G$26 -> 20000 | K16: =Assumptions!$G$26 -> 20000 | L16: =Assumptions!$G$26 -> 20000
C17: 假设追加资金（未承诺） | D17: =Financing!D8 -> 103000 | E17: =Financing!D8 -> 103000 | F17: =Financing!D8 -> 103000 | G17: =Financing!E8 -> 281100 | H17: =Financing!E8 -> 281100 | I17: =Financing!E8 -> 281100 | J17: =Financing!F8 -> 75430 | K17: =Financing!F8 -> 75430 | L17: =Financing!F8 -> 75430
C18: 累计经营损益 | D18: =SUM(Costs!D19:O19) -> -60640 | E18: =SUM(Costs!D19:AA19) -> -69040 | F18: =SUM(Costs!D19:AM19) -> -14720 | G18: =SUM(Costs!D43:O43) -> -95200 | H18: =SUM(Costs!D43:AA43) -> -188000 | I18: =SUM(Costs!D43:AM43) -> -278400 | J18: =SUM(Costs!D67:O67) -> -48940 | K18: =SUM(Costs!D67:AA67) -> 4200 | L18: =SUM(Costs!D67:AM67) -> 180440
C19: 负债及权益合计 | D19: =SUM(D15:D18) -> 62360 | E19: =SUM(E15:E18) -> 53960 | F19: =SUM(F15:F18) -> 108280 | G19: =SUM(G15:G18) -> 205900 | H19: =SUM(H15:H18) -> 113100 | I19: =SUM(I15:I18) -> 22700 | J19: =SUM(J15:J18) -> 46490 | K19: =SUM(K15:K18) -> 99630 | L19: =SUM(L15:L18) -> 275870
C21: 资产减负债及权益 | D21: =D13-D19 -> 0 | E21: =E13-E19 -> -5.8207661e-11 | F21: =F13-F19 -> 0 | G21: =G13-G19 -> 0 | H21: =H13-H19 -> 0 | I21: =I13-I19 -> 5.8207661e-11 | J21: =J13-J19 -> 0 | K21: =K13-K19 -> 0 | L21: =L13-L19 -> 0

Sheet Cash Flow
C2: Blocky | 月度现金流
C3: 人民币 · 2027–2029示例测算
C6: 基准 | D6: 46388 | E6: 46419 | F6: 46447 | G6: 46478 | H6: 46508 | I6: 46539 | J6: 46569 | K6: 46600 | L6: 46631 | M6: 46661 | N6: 46692 | O6: 46722 | P6: 46753 | Q6: 46784 | R6: 46813 | S6: 46844 | T6: 46874 | U6: 46905 | V6: 46935 | W6: 46966 | X6: 46997 | Y6: 47027 | Z6: 47058 | AA6: 47088 | AB6: 47119 | AC6: 47150 | AD6: 47178 | AE6: 47209 | AF6: 47239 | AG6: 47270 | AH6: 47300 | AI6: 47331 | AJ6: 47362 | AK6: 47392 | AL6: 47423 | AM6: 47453
C7: 机构服务收入 | D7: =Revenue!D9 -> 0 | E7: =Revenue!E9 -> 0 | F7: =Revenue!F9 -> 0 | G7: =Revenue!G9 -> 18000 | H7: =Revenue!H9 -> 0 | I7: =Revenue!I9 -> 18000 | J7: =Revenue!J9 -> 0 | K7: =Revenue!K9 -> 0 | ... AM7: =Revenue!AM9 -> 18000
C8: 当月收款 | D8: =Revenue!D10 -> 0 | E8: =Revenue!E10 -> 0 | F8: =Revenue!F10 -> 0 | G8: =Revenue!G10 -> 9000 | H8: =Revenue!H10 -> 9000 | I8: =Revenue!I10 -> 9000 | J8: =Revenue!J10 -> 9000 | K8: =Revenue!K10 -> 0 | ... AM8: =Revenue!AM10 -> 27000
C9: 现金费用 | D9: =Costs!D18 -> 7800 | E9: =Costs!E18 -> 7800 | F9: =Costs!F18 -> 7800 | G9: =Costs!G18 -> 16560 | H9: =Costs!H18 -> 7800 | I9: =Costs!I18 -> 16560 | J9: =Costs!J18 -> 7800 | K9: =Costs!K18 -> 7800 | ... AM9: =Costs!AM18 -> 16560
C10: 设备支出 | D10: =Costs!D15 -> 12000 | E10: =Costs!E15 -> 0 | F10: =Costs!F15 -> 0 | G10: =Costs!G15 -> 0 | H10: =Costs!H15 -> 0 | I10: =Costs!I15 -> 0 | J10: =Costs!J15 -> 0 | K10: =Costs!K15 -> 0 | ... AM10: =Costs!AM15 -> 0
C11: 经营及投资净现金 | D11: =D8-D9-D10 -> -19800 | E11: =E8-E9-E10 -> -7800 | F11: =F8-F9-F10 -> -7800 | G11: =G8-G9-G10 -> -7560 | H11: =H8-H9-H10 -> 1200 | I11: =I8-I9-I10 -> -7560 | J11: =J8-J9-J10 -> 1200 | K11: =K8-K9-K10 -> -7800 | ... AM11: =AM8-AM9-AM10 -> 10440
C12: 期末现金（未覆盖缺口） | D12: =D11+Assumptions!$E$26 -> 200 | E12: =E11+D12 -> -7600 | F12: =F11+E12 -> -15400 | G12: =G11+F12 -> -22960 | H12: =H11+G12 -> -21760 | I12: =I11+H12 -> -29320 | J12: =J11+I12 -> -28120 | K12: =K11+J12 -> -35920 | L12: =L11+K12 -> -43480 | ... AM12: =AM11+AL12 -> -3720
C13: 假设追加资金（未承诺） | D13: =Financing!D8 -> 103000 | E13: =0 -> 0 | F13: =0 -> 0 | G13: =0 -> 0 | H13: =0 -> 0 | I13: =0 -> 0 | J13: =0 -> 0 | K13: =0 -> 0 | L13: =0 -> 0 | ... AM13: =0 -> 0
C14: 期末现金（假设缺口已覆盖） | D14: =D12+SUM($D13:D13) -> 103200 | E14: =E12+SUM($D13:E13) -> 95400 | F14: =F12+SUM($D13:F13) -> 87600 | G14: =G12+SUM($D13:G13) -> 80040 | H14: =H12+SUM($D13:H13) -> 81240 | I14: =I12+SUM($D13:I13) -> 73680 | J14: =J12+SUM($D13:J13) -> 74880 | K14: =K12+SUM($D13:K13) -> 67080 | ... AM14: =AM12+SUM($D13:AM13) -> 99280
C15: 最低储备 | D15: =Assumptions!$E$27 -> 20000 | E15: =Assumptions!$E$27 -> 20000 | F15: =Assumptions!$E$27 -> 20000 | G15: =Assumptions!$E$27 -> 20000 | H15: =Assumptions!$E$27 -> 20000 | I15: =Assumptions!$E$27 -> 20000 | J15: =Assumptions!$E$27 -> 20000 | K15: =Assumptions!$E$27 -> 20000 | ... AM15: =Assumptions!$E$27 -> 20000
C16: 储备差额 | D16: =D14-D15 -> 83200 | E16: =E14-E15 -> 75400 | F16: =F14-F15 -> 67600 | G16: =G14-G15 -> 60040 | H16: =H14-H15 -> 61240 | I16: =I14-I15 -> 53680 | J16: =J14-J15 -> 54880 | K16: =K14-K15 -> 47080 | ... AM16: =AM14-AM15 -> 79280
C30: 悲观 | D30: 46388 | E30: 46419 | F30: 46447 | G30: 46478 | H30: 46508 | I30: 46539 | J30: 46569 | K30: 46600 | L30: 46631 | M30: 46661 | N30: 46692 | O30: 46722 | P30: 46753 | Q30: 46784 | R30: 46813 | S30: 46844 | T30: 46874 | U30: 46905 | V30: 46935 | W30: 46966 | X30: 46997 | Y30: 47027 | Z30: 47058 | AA30: 47088 | AB30: 47119 | AC30: 47150 | AD30: 47178 | AE30: 47209 | AF30: 47239 | AG30: 47270 | AH30: 47300 | AI30: 47331 | AJ30: 47362 | AK30: 47392 | AL30: 47423 | AM30: 47453
C31: 机构服务收入 | D31: =Revenue!D27 -> 0 | E31: =Revenue!E27 -> 0 | F31: =Revenue!F27 -> 0 | G31: =Revenue!G27 -> 0 | H31: =Revenue!H27 -> 15000 | I31: =Revenue!I27 -> 0 | J31: =Revenue!J27 -> 0 | K31: =Revenue!K27 -> 0 | ... AM31: =Revenue!AM27 -> 0
C32: 当月收款 | D32: =Revenue!D28 -> 0 | E32: =Revenue!E28 -> 0 | F32: =Revenue!F28 -> 0 | G32: =Revenue!G28 -> 0 | H32: =Revenue!H28 -> 4500 | I32: =Revenue!I28 -> 10500 | J32: =Revenue!J28 -> 0 | K32: =Revenue!K28 -> 0 | ... AM32: =Revenue!AM28 -> 10500
C33: 现金费用 | D33: =Costs!D42 -> 7800 | E33: =Costs!E42 -> 7800 | F33: =Costs!F42 -> 7800 | G33: =Costs!G42 -> 7800 | H33: =Costs!H42 -> 21600 | I33: =Costs!I42 -> 7800 | J33: =Costs!J42 -> 7800 | K33: =Costs!K42 -> 7800 | ... AM33: =Costs!AM42 -> 7800
C34: 设备支出 | D34: =Costs!D39 -> 12000 | E34: =Costs!E39 -> 0 | F34: =Costs!F39 -> 0 | G34: =Costs!G39 -> 0 | H34: =Costs!H39 -> 0 | I34: =Costs!I39 -> 0 | J34: =Costs!J39 -> 0 | K34: =Costs!K39 -> 0 | ... AM34: =Costs!AM39 -> 0
C35: 经营及投资净现金 | D35: =D32-D33-D34 -> -19800 | E35: =E32-E33-E34 -> -7800 | F35: =F32-F33-F34 -> -7800 | G35: =G32-G33-G34 -> -7800 | H35: =H32-H33-H34 -> -17100 | I35: =I32-I33-I34 -> 2700 | J35: =J32-J33-J34 -> -7800 | K35: =K32-K33-K34 -> -7800 | ... AM35: =AM32-AM33-AM34 -> 2700
C36: 期末现金（未覆盖缺口） | D36: =D35+Assumptions!$F$26 -> 200 | E36: =E35+D36 -> -7600 | F36: =F35+E36 -> -15400 | G36: =G35+F36 -> -23200 | H36: =H35+G36 -> -40300 | I36: =I35+H36 -> -37600 | J36: =J35+I36 -> -45400 | K36: =K35+J36 -> -53200 | L36: =L35+K36 -> -61000 | ... AM36: =AM35+AL36 -> -258400
C37: 假设追加资金（未承诺） | D37: =Financing!E8 -> 281100 | E37: =0 -> 0 | F37: =0 -> 0 | G37: =0 -> 0 | H37: =0 -> 0 | I37: =0 -> 0 | J37: =0 -> 0 | K37: =0 -> 0 | L37: =0 -> 0 | ... AM37: =0 -> 0
C38: 期末现金（假设缺口已覆盖） | D38: =D36+SUM($D37:D37) -> 281300 | E38: =E36+SUM($D37:E37) -> 273500 | F38: =F36+SUM($D37:F37) -> 265700 | G38: =G36+SUM($D37:G37) -> 257900 | H38: =H36+SUM($D37:H37) -> 240800 | I38: =I36+SUM($D37:I37) -> 243500 | J38: =J36+SUM($D37:J37) -> 235700 | K38: =K36+SUM($D37:K37) -> 227900 | ... AM38: =AM36+SUM($D37:AM37) -> 22700
C39: 最低储备 | D39: =Assumptions!$F$27 -> 20000 | E39: =Assumptions!$F$27 -> 20000 | F39: =Assumptions!$F$27 -> 20000 | G39: =Assumptions!$F$27 -> 20000 | H39: =Assumptions!$F$27 -> 20000 | I39: =Assumptions!$F$27 -> 20000 | J39: =Assumptions!$F$27 -> 20000 | K39: =Assumptions!$F$27 -> 20000 | ... AM39: =Assumptions!$F$27 -> 20000
C40: 储备差额 | D40: =D38-D39 -> 261300 | E40: =E38-E39 -> 253500 | F40: =F38-F39 -> 245700 | G40: =G38-G39 -> 237900 | H40: =H38-H39 -> 220800 | I40: =I38-I39 -> 223500 | J40: =J38-J39 -> 215700 | K40: =K38-K39 -> 207900 | ... AM40: =AM38-AM39 -> 2700
